<?xml version="1.0" ?>
<!-- =================================================================================== -->
<!-- |    This document was autogenerated by xacro from rbroboutNoSensors.urdf.xacro   | -->
<!-- |    EDITING THIS FILE BY HAND IS NOT RECOMMENDED                                 | -->
<!-- =================================================================================== -->
<robot name="rbrobout">
  <!-- ***************** -->
  <!-- Imported elements -->
  <!-- ***************** -->
  <!-- First we import all posible elements defined in the urdf.xacro files. All these elements are defined as macro:xacros -->
  <gazebo reference="base_footprint">
    <material>Gazebo/Green</material>
  </gazebo>
  <!-- in kg-->
  <!-- Import all available sensors -->
  <!-- xacro:include filename="/home/joel/ros2_ws/src/nombre_paquete/urdf/all_sensors.urdf.xacro" /-->
  <!-- source en.wikipedia.org/wiki/List_of_moments_of_inertia-->
  <!-- Includes -->
  <gazebo>
    <plugin filename="libgazebo_ros_control.so" name="ros_control">
      <robotParam>robot_description</robotParam>
      <controlPeriod>0.001</controlPeriod>
      <robotSimType>gazebo_ros_control/DefaultRobotHWSim</robotSimType>
      <legacyModeNS>true</legacyModeNS>
    </plugin>
  </gazebo>
  <!-- *************** -->
  <!-- Robots Elements -->
  <!-- *************** -->
  <!-- Here we create the robot elements using the xacro:macros imported at the beggining of this file -->
  <link name="rbrobout_base_footprint">
    <visual>
      <origin rpy="0 0 0" xyz="0 0 0"/>
      <geometry>
        <box size="0.001 0.001 0.001"/>
      </geometry>
    </visual>
  </link>
  <joint name="rbrobout_base_footprint_joint" type="fixed">
    <origin rpy="0 0 0" xyz="0 0 0.127"/>
    <!-- ${wheel_radius} property must be defined inside wheel description -->
    <parent link="rbrobout_base_footprint"/>
    <child link="rbrobout_base_link"/>
  </joint>
  <!-- BASE_LINK -->
  <link name="rbrobout_base_link">
    <inertial>
      <mass value="200.0"/>
      <origin xyz="0 0 0"/>
      <inertia ixx="1.391" ixy="0.004" ixz="0.0" iyy="6.853" iyz="0.0" izz="6.125"/>
    </inertial>
    <visual>
      <origin rpy="0 0 0" xyz="0 0 0"/>
      <geometry>
        <mesh filename="/home/joel/ros2_ws/src/nombre_paquete/urdf/rbrobout_base.gazebo.xacro/models/robout_chassis.stl"/>
      </geometry>
      <material name="darkgrey">
        <color rgba="0.1 0.1 0.1 1"/>
      </material>
    </visual>
    <collision>
      <origin rpy="0 0 0 " xyz="0 0 0"/>
      <geometry>
        <mesh filename="/home/joel/ros2_ws/src/nombre_paquete/urdf/models/robout_chassis.stl"/>
      </geometry>
    </collision>
  </link>
  <!-- DOCKING CONTACTS -->
  <!-- <joint name="${prefix}base_docking_joint" type="fixed">
			<origin xyz="0.284 0.012 0.068" rpy="0 0 0 " />
			<parent link="${prefix}base_link"/>
			<child link="${prefix}base_docking_contact_link" />
		</joint> -->
  <!-- DOCKING LINK -->
  <!-- <link name="${prefix}base_docking_contact_link" /> -->
  <joint name="rbrobout_front_right_wheel_joint" type="continuous">
    <parent link="rbrobout_base_link"/>
    <child link="rbrobout_front_right_wheel_link"/>
    <origin rpy="1.57 0 0" xyz="0.558 -0.2865 0.0"/>
    <axis rpy="0 0 0" xyz="0 0 1"/>
    <limit effort="100" velocity="100"/>
    <joint_properties damping="0.0" friction="0.0"/>
  </joint>
  <link name="rbrobout_front_right_wheel_link">
    <visual>
      <origin rpy="0 0 0" xyz="0 0 0"/>
      <geometry>
        <mesh filename="/home/joel/ros2_ws/src/nombre_paquete/urdf/models/robout_wheel.stl"/>
      </geometry>
      <material name="darkgrey">
        <color rgba="0.2 0.2 0.2 1"/>
      </material>
    </visual>
    <collision>
      <origin rpy="0 0 0" xyz="0 0 0"/>
      <geometry>
        <cylinder length="0.128" radius="0.127"/>
      </geometry>
    </collision>
    <inertial>
      <mass value="15"/>
      <origin xyz="0 0 0"/>
      <inertia ixx="0.08096374999999999" ixy="0" ixz="0" iyy="0.1209675" iyz="0" izz="0.08096374999999999"/>
    </inertial>
  </link>
  <!-- Transmission is important to link the joints and the controller (see summit_xl_control/config/summit_xl_control.yaml)-->
  <transmission name="rbrobout_front_right_wheel_joint_trans">
    <type>transmission_interface/SimpleTransmission</type>
    <joint name="rbrobout_front_right_wheel_joint">
      <hardwareInterface>hardware_interface/VelocityJointInterface</hardwareInterface>
    </joint>
    <actuator name="rbrobout_front_right_wheel_joint_motor">
      <mechanicalReduction>1</mechanicalReduction>
    </actuator>
  </transmission>
  <gazebo reference="rbrobout_front_right_wheel_link">
    <mu1 value="0.0"/>
    <mu2 value="0.0"/>
    <kp value="10000000.0"/>
    <kd value="1.0"/>
    <fdir1 value="1 0 0"/>
    <turnGravityOff>false</turnGravityOff>
  </gazebo>
  <joint name="rbrobout_front_left_wheel_joint" type="continuous">
    <parent link="rbrobout_base_link"/>
    <child link="rbrobout_front_left_wheel_link"/>
    <origin rpy="1.57 0 0" xyz="0.558 0.2865 0.0"/>
    <axis rpy="0 0 0" xyz="0 0 1"/>
    <limit effort="100" velocity="100"/>
    <joint_properties damping="0.0" friction="0.0"/>
  </joint>
  <link name="rbrobout_front_left_wheel_link">
    <visual>
      <origin rpy="0 0 0" xyz="0 0 0"/>
      <geometry>
        <mesh filename="/home/joel/ros2_ws/src/nombre_paquete/urdf/models/robout_wheel.stl"/>
      </geometry>
      <material name="darkgrey">
        <color rgba="0.2 0.2 0.2 1"/>
      </material>
    </visual>
    <collision>
      <origin rpy="0 0 0" xyz="0 0 0"/>
      <geometry>
        <cylinder length="0.128" radius="0.127"/>
      </geometry>
    </collision>
    <inertial>
      <mass value="15"/>
      <origin xyz="0 0 0"/>
      <inertia ixx="0.08096374999999999" ixy="0" ixz="0" iyy="0.1209675" iyz="0" izz="0.08096374999999999"/>
    </inertial>
  </link>
  <!-- Transmission is important to link the joints and the controller (see summit_xl_control/config/summit_xl_control.yaml)-->
  <transmission name="rbrobout_front_left_wheel_joint_trans">
    <type>transmission_interface/SimpleTransmission</type>
    <joint name="rbrobout_front_left_wheel_joint">
      <hardwareInterface>hardware_interface/VelocityJointInterface</hardwareInterface>
    </joint>
    <actuator name="rbrobout_front_left_wheel_joint_motor">
      <mechanicalReduction>1</mechanicalReduction>
    </actuator>
  </transmission>
  <gazebo reference="rbrobout_front_left_wheel_link">
    <mu1 value="0.0"/>
    <mu2 value="0.0"/>
    <kp value="10000000.0"/>
    <kd value="1.0"/>
    <fdir1 value="1 0 0"/>
    <turnGravityOff>false</turnGravityOff>
  </gazebo>
  <joint name="rbrobout_back_left_wheel_joint" type="continuous">
    <parent link="rbrobout_base_link"/>
    <child link="rbrobout_back_left_wheel_link"/>
    <origin rpy="1.57 0 0" xyz="-0.558 0.2865 0.0"/>
    <axis rpy="0 0 0" xyz="0 0 1"/>
    <limit effort="100" velocity="100"/>
    <joint_properties damping="0.0" friction="0.0"/>
  </joint>
  <link name="rbrobout_back_left_wheel_link">
    <visual>
      <origin rpy="0 0 0" xyz="0 0 0"/>
      <geometry>
        <mesh filename="/home/joel/ros2_ws/src/nombre_paquete/urdf/models/robout_wheel.stl"/>
      </geometry>
      <material name="darkgrey">
        <color rgba="0.2 0.2 0.2 1"/>
      </material>
    </visual>
    <collision>
      <origin rpy="0 0 0" xyz="0 0 0"/>
      <geometry>
        <cylinder length="0.128" radius="0.127"/>
      </geometry>
    </collision>
    <inertial>
      <mass value="15"/>
      <origin xyz="0 0 0"/>
      <inertia ixx="0.08096374999999999" ixy="0" ixz="0" iyy="0.1209675" iyz="0" izz="0.08096374999999999"/>
    </inertial>
  </link>
  <!-- Transmission is important to link the joints and the controller (see summit_xl_control/config/summit_xl_control.yaml)-->
  <transmission name="rbrobout_back_left_wheel_joint_trans">
    <type>transmission_interface/SimpleTransmission</type>
    <joint name="rbrobout_back_left_wheel_joint">
      <hardwareInterface>hardware_interface/VelocityJointInterface</hardwareInterface>
    </joint>
    <actuator name="rbrobout_back_left_wheel_joint_motor">
      <mechanicalReduction>1</mechanicalReduction>
    </actuator>
  </transmission>
  <gazebo reference="rbrobout_back_left_wheel_link">
    <mu1 value="0.0"/>
    <mu2 value="0.0"/>
    <kp value="10000000.0"/>
    <kd value="1.0"/>
    <fdir1 value="1 0 0"/>
    <turnGravityOff>false</turnGravityOff>
  </gazebo>
  <joint name="rbrobout_back_right_wheel_joint" type="continuous">
    <parent link="rbrobout_base_link"/>
    <child link="rbrobout_back_right_wheel_link"/>
    <origin rpy="1.57 0 0" xyz="-0.558 -0.2865 0.0"/>
    <axis rpy="0 0 0" xyz="0 0 1"/>
    <limit effort="100" velocity="100"/>
    <joint_properties damping="0.0" friction="0.0"/>
  </joint>
  <link name="rbrobout_back_right_wheel_link">
    <visual>
      <origin rpy="0 0 0" xyz="0 0 0"/>
      <geometry>
        <mesh filename="/home/joel/ros2_ws/src/nombre_paquete/urdf/models/robout_wheel.stl"/>
      </geometry>
      <material name="darkgrey">
        <color rgba="0.2 0.2 0.2 1"/>
      </material>
    </visual>
    <collision>
      <origin rpy="0 0 0" xyz="0 0 0"/>
      <geometry>
        <cylinder length="0.128" radius="0.127"/>
      </geometry>
    </collision>
    <inertial>
      <mass value="15"/>
      <origin xyz="0 0 0"/>
      <inertia ixx="0.08096374999999999" ixy="0" ixz="0" iyy="0.1209675" iyz="0" izz="0.08096374999999999"/>
    </inertial>
  </link>
  <!-- Transmission is important to link the joints and the controller (see summit_xl_control/config/summit_xl_control.yaml)-->
  <transmission name="rbrobout_back_right_wheel_joint_trans">
    <type>transmission_interface/SimpleTransmission</type>
    <joint name="rbrobout_back_right_wheel_joint">
      <hardwareInterface>hardware_interface/VelocityJointInterface</hardwareInterface>
    </joint>
    <actuator name="rbrobout_back_right_wheel_joint_motor">
      <mechanicalReduction>1</mechanicalReduction>
    </actuator>
  </transmission>
  <gazebo reference="rbrobout_back_right_wheel_link">
    <mu1 value="0.0"/>
    <mu2 value="0.0"/>
    <kp value="10000000.0"/>
    <kd value="1.0"/>
    <fdir1 value="1 0 0"/>
    <turnGravityOff>false</turnGravityOff>
  </gazebo>
</robot>
