#VRML_SIM R2025a utf8
# license: Apache License 2.0
# license url: http://www.apache.org/licenses/LICENSE-2.0
# This is a proto file for Webots for the rbroboutNoSensors
# Extracted from: /home/joel/webots_prueba/Prueba3/URDF/rbroboutNoSensors.urdf

PROTO rbroboutNoSensors [
  field  SFVec3f     translation     0 0 0
  field  SFRotation  rotation        0 0 1 0
  field  SFString    name            "rbroboutNoSensors"  # Is `Robot.name`.
  field  SFString    controller      "void"               # Is `Robot.controller`.
  field  MFString    controllerArgs  []                   # Is `Robot.controllerArgs`.
  field  SFString    customData      ""                   # Is `Robot.customData`.
  field  SFBool      supervisor      FALSE                # Is `Robot.supervisor`.
  field  SFBool      synchronization TRUE                 # Is `Robot.synchronization`.
  field  SFBool      selfCollision   FALSE                # Is `Robot.selfCollision`.
  field  MFNode      toolSlot        []                   # Extend the robot with new nodes at the end of the arm.
]
{
  Robot {
    translation IS translation
    rotation IS rotation
    controller IS controller
    controllerArgs IS controllerArgs
    customData IS customData
    supervisor IS supervisor
    synchronization IS synchronization
    selfCollision IS selfCollision
    children [
      Shape {
        appearance PBRAppearance {
          baseColor 0.500000 0.500000 0.500000
          roughness 1.000000
          metalness 0
        }
        geometry Box {
           size 0.001000 0.001000 0.001000
        }
      }
      Solid {
        translation 0.000000 0.000000 0.127000
        children [
          Shape {
            appearance DEF darkgrey PBRAppearance {
              baseColor 0.100000 0.100000 0.100000
              roughness 1.000000
              metalness 0
            }
            geometry DEF robout_chassis Mesh {
              url "/home/joel/ros2_ws/src/nombre_paquete/urdf/rbrobout_base.gazebo.xacro/models/robout_chassis.stl"
            }
          }
          HingeJoint {
            jointParameters HingeJointParameters {
              axis 0.000000 -1.000000 0.000796
              anchor 0.558000 -0.286500 0.000000
            }
            device [
              RotationalMotor {
                name "rbrobout_front_right_wheel_joint"
                maxVelocity 100.0
                maxTorque 100.0
              }
              PositionSensor {
                name "rbrobout_front_right_wheel_joint_sensor"
              }
            ]
            endPoint Solid {
              translation 0.558000 -0.286500 0.000000
              rotation 1.000000 0.000000 0.000000 1.570000
              children [
                Shape {
                  appearance USE darkgrey
                  geometry DEF robout_wheel Mesh {
                    url "/home/joel/ros2_ws/src/nombre_paquete/urdf/models/robout_wheel.stl"
                  }
                }
              ]
              name "rbrobout_front_right_wheel_link"
              boundingObject Cylinder {
                radius 0.127
                height 0.128
              }
              physics Physics {
                density -1
                mass 15.000000
                centerOfMass [ 0.000000 0.000000 0.000000 ]
                inertiaMatrix [
                  8.096375e-02 1.209675e-01 8.096375e-02
                  0.000000e+00 0.000000e+00 0.000000e+00
                ]
              }
            }
          }
          HingeJoint {
            jointParameters HingeJointParameters {
              axis 0.000000 -1.000000 0.000796
              anchor 0.558000 0.286500 0.000000
            }
            device [
              RotationalMotor {
                name "rbrobout_front_left_wheel_joint"
                maxVelocity 100.0
                maxTorque 100.0
              }
              PositionSensor {
                name "rbrobout_front_left_wheel_joint_sensor"
              }
            ]
            endPoint Solid {
              translation 0.558000 0.286500 0.000000
              rotation 1.000000 0.000000 0.000000 1.570000
              children [
                Shape {
                  appearance USE darkgrey
                  geometry USE robout_wheel
                }
              ]
              name "rbrobout_front_left_wheel_link"
              boundingObject Cylinder {
                radius 0.127
                height 0.128
              }
              physics Physics {
                density -1
                mass 15.000000
                centerOfMass [ 0.000000 0.000000 0.000000 ]
                inertiaMatrix [
                  8.096375e-02 1.209675e-01 8.096375e-02
                  0.000000e+00 0.000000e+00 0.000000e+00
                ]
              }
            }
          }
          HingeJoint {
            jointParameters HingeJointParameters {
              axis 0.000000 -1.000000 0.000796
              anchor -0.558000 0.286500 0.000000
            }
            device [
              RotationalMotor {
                name "rbrobout_back_left_wheel_joint"
                maxVelocity 100.0
                maxTorque 100.0
              }
              PositionSensor {
                name "rbrobout_back_left_wheel_joint_sensor"
              }
            ]
            endPoint Solid {
              translation -0.558000 0.286500 0.000000
              rotation 1.000000 0.000000 0.000000 1.570000
              children [
                Shape {
                  appearance USE darkgrey
                  geometry USE robout_wheel
                }
              ]
              name "rbrobout_back_left_wheel_link"
              boundingObject Cylinder {
                radius 0.127
                height 0.128
              }
              physics Physics {
                density -1
                mass 15.000000
                centerOfMass [ 0.000000 0.000000 0.000000 ]
                inertiaMatrix [
                  8.096375e-02 1.209675e-01 8.096375e-02
                  0.000000e+00 0.000000e+00 0.000000e+00
                ]
              }
            }
          }
          HingeJoint {
            jointParameters HingeJointParameters {
              axis 0.000000 -1.000000 0.000796
              anchor -0.558000 -0.286500 0.000000
            }
            device [
              RotationalMotor {
                name "rbrobout_back_right_wheel_joint"
                maxVelocity 100.0
                maxTorque 100.0
              }
              PositionSensor {
                name "rbrobout_back_right_wheel_joint_sensor"
              }
            ]
            endPoint Solid {
              translation -0.558000 -0.286500 0.000000
              rotation 1.000000 0.000000 0.000000 1.570000
              children [
                Shape {
                  appearance USE darkgrey
                  geometry USE robout_wheel
                }
              ]
              name "rbrobout_back_right_wheel_link"
              boundingObject Cylinder {
                radius 0.127
                height 0.128
              }
              physics Physics {
                density -1
                mass 15.000000
                centerOfMass [ 0.000000 0.000000 0.000000 ]
                inertiaMatrix [
                  8.096375e-02 1.209675e-01 8.096375e-02
                  0.000000e+00 0.000000e+00 0.000000e+00
                ]
              }
            }
          }
        ]
        name "rbrobout_base_link"
        boundingObject USE robout_chassis
        physics Physics {
          density -1
          mass 200.000000
          centerOfMass [ 0.000000 0.000000 0.000000 ]
          inertiaMatrix [
            1.391000e+00 6.853000e+00 6.125000e+00
            4.000000e-03 0.000000e+00 0.000000e+00
          ]
        }
      }
    ]
    name IS name
  }
}
