<?xml version="1.0" ?>
<!-- =================================================================================== -->
<!-- |    This document was autogenerated by xacro from rbtheron.urdf.xacro            | -->
<!-- |    EDITING THIS FILE BY HAND IS NOT RECOMMENDED                                 | -->
<!-- =================================================================================== -->
<robot name="rb_theron">
  <!-- ***************** -->
  <!-- Imported elements -->
  <!-- ***************** -->
  <!-- First we import all posible elements defined in the urdf.xacro files. All these elements are defined as macro:xacros -->
  <!-- in kg-->
  <!-- in kg-->
  <!-- in kg-->
  <!-- This file unifies all sensors that can be used on simulation, defined as xacro:macros -->
  <!-- source en.wikipedia.org/wiki/List_of_moments_of_inertia-->
  <!-- $(find robotnik_sensors_gazebo)/config/camera/axis_m5013.yaml -->
  <!-- $(find robotnik_sensors_gazebo)/config/camera/axis_m5074.yaml-->
  <!-- $(find robotnik_sensors_gazebo)/config/camera/axis_m5525.yaml -->
  <!--$(find robotnik_sensors_gazebo)/config/camera/axis_m5526.yaml-->
  <!-- ***************** -->
  <!-- Global parameters -->
  <!-- ***************** -->
  <!-- Second we define all the parameters and arguments to customize the robot characteristics -->
  <!-- Here we create the robot using the xacro:macro imported at the beggining of this file -->
  <!-- *************** -->
  <!-- Robots Elements -->
  <!-- *************** -->
  <!-- Here we create the robot elements using the xacro:macros imported at the beggining of this file -->
  <!-- BASE FOOTPRINT -->
  <link name="robot_base_footprint">
    <visual>
      <origin rpy="0 0 0" xyz="0 0 0"/>
      <geometry>
        <box size="0.001 0.001 0.001"/>
      </geometry>
    </visual>
  </link>
  <joint name="robot_base_footprint_joint" type="fixed">
    <origin rpy="0 0 0" xyz="0 0 0.0762"/>
    <!-- ${wheel_radius} property must be defined inside wheel description -->
    <parent link="robot_base_footprint"/>
    <child link="robot_base_link"/>
  </joint>
  <!-- BASE_LINK -->
  <link name="robot_base_link">
    <inertial>
      <mass value="45.0"/>
      <origin xyz="0 0 0"/>
      <inertia ixx="1.391" ixy="0.004" ixz="0.0" iyy="6.853" iyz="0.0" izz="6.125"/>
    </inertial>
    <visual>
      <origin rpy="0 0 0" xyz="0 0 0"/>
      <geometry>
        <mesh filename="package://robot_description/meshes/bases/rbtheron/theron_base_v4.stl"/>
      </geometry>
      <material name="black">
        <color rgba="0.0 0.0 0.0 1"/>
      </material>
    </visual>
    <collision>
      <origin rpy="0 0 0" xyz="0 0 0"/>
      <geometry>
        <mesh filename="package://robot_description/meshes/bases/rbtheron/theron_base_v4.stl"/>
      </geometry>
    </collision>
  </link>
  <gazebo reference="robot_base_link">
    <material>Gazebo/Black</material>
  </gazebo>
  <!-- LOGO ROBOTNIK IZQUIERDO -->
  <link name="robot_base_logo_left">
    <visual>
      <origin rpy="0 0 0" xyz="0 0 0"/>
      <geometry>
        <mesh filename="package://robot_description/meshes/bases/robotnik_logo_chasis.stl"/>
      </geometry>
      <material name="darkgrey">
        <color rgba="0.5 0.5 0.5 1"/>
      </material>
    </visual>
  </link>
  <joint name="robot_base_logo_left_joint" type="fixed">
    <origin rpy="0 0 0" xyz="0.0 0.28931 0.19062"/>
    <parent link="robot_base_link"/>
    <child link="robot_base_logo_left"/>
  </joint>
  <!-- LOGO ROBOTNIK DERECHO -->
  <link name="robot_base_logo_right">
    <visual>
      <origin rpy="0 0 0" xyz="0 0 0"/>
      <geometry>
        <mesh filename="package://robot_description/meshes/bases/robotnik_logo_chasis.stl"/>
      </geometry>
      <material name="darkgrey">
        <color rgba="0.5 0.5 0.5 1"/>
      </material>
    </visual>
  </link>
  <joint name="robot_base_logo_right_joint" type="fixed">
    <origin rpy="0 0 3.141592653589793" xyz="0.0 -0.28931 0.19062"/>
    <parent link="robot_base_link"/>
    <child link="robot_base_logo_right"/>
  </joint>
  <!-- LOGO ROBOTNIK FRONTAL -->
  <link name="robot_base_logo_front">
    <visual>
      <origin rpy="0 0 0" xyz="0 0 0"/>
      <geometry>
        <mesh filename="package://robot_description/meshes/bases/robotnik_logo_chasis.stl"/>
      </geometry>
      <material name="darkgrey">
        <color rgba="0.5 0.5 0.5 1"/>
      </material>
    </visual>
  </link>
  <joint name="robot_base_logo_front_joint" type="fixed">
    <origin rpy="0 0 -1.5707963267948966" xyz="0.345 0.0 0.0"/>
    <parent link="robot_base_link"/>
    <child link="robot_base_logo_front"/>
  </joint>
  <!-- LOGO ROBOTNIK TRASERO -->
  <link name="robot_base_logo_rear">
    <visual>
      <origin rpy="0 0 0" xyz="0 0 0"/>
      <geometry>
        <mesh filename="package://robot_description/meshes/bases/robotnik_logo_chasis.stl"/>
      </geometry>
      <material name="darkgrey">
        <color rgba="0.5 0.5 0.5 1"/>
      </material>
    </visual>
  </link>
  <joint name="robot_base_logo_rear_joint" type="fixed">
    <origin rpy="0 0 1.5707963267948966" xyz="-0.345 0.0 0.0"/>
    <parent link="robot_base_link"/>
    <child link="robot_base_logo_rear"/>
  </joint>
  <!-- DOCKING CONTACT -->
  <link name="robot_base_docking_contact">
    </link>
  <joint name="robot_base_docking_joint" type="fixed">
    <origin rpy="0 0 0" xyz="0.35 0 0.09"/>
    <parent link="robot_base_link"/>
    <child link="robot_base_docking_contact"/>
  </joint>
  <!--WHEEL TIRE -->
  <joint name="robot_right_wheel_joint" type="continuous">
    <parent link="robot_base_link"/>
    <child link="robot_right_wheel_link"/>
    <origin rpy="0 0 0" xyz="0 -0.2516 0.0"/>
    <axis rpy="0 0 0" xyz="0 1 0"/>
    <limit effort="100" velocity="100"/>
    <joint_properties damping="0.0" friction="0.0"/>
  </joint>
  <link name="robot_right_wheel_link">
    <visual>
      <!-- HIGH RESOLUTION WHEELS -->
      <!-- LOW RESOLUTION WHEELS -->
      <origin rpy="1.5707963267948966 0 0" xyz="0 0 0"/>
      <geometry>
        <cylinder length="0.025" radius="0.0762"/>
      </geometry>
    </visual>
    <collision>
      <origin rpy="1.5707963267948966 0 0" xyz="0 0 0"/>
      <geometry>
        <cylinder length="0.025" radius="0.0762"/>
      </geometry>
    </collision>
    <inertial>
      <mass value="1"/>
      <origin rpy="3.141592653589793 0 0" xyz="0 0 0"/>
      <inertia ixx="0.0015036933333333335" ixy="0" ixz="0" iyy="0.0015036933333333335" iyz="0" izz="0.00290322"/>
    </inertial>
  </link>
  <joint name="robot_right_wheel_tire_joint" type="fixed">
    <parent link="robot_right_wheel_link"/>
    <child link="robot_right_wheel_tire_link"/>
    <origin rpy="0 0 0" xyz="0 0 0"/>
  </joint>
  <link name="robot_right_wheel_tire_link">
    <visual>
      <origin rpy="1.5707963267948966 0 0" xyz="0 0 0"/>
      <geometry>
        <cylinder length="0.026000000000000002" radius="0.070104"/>
      </geometry>
    </visual>
  </link>
  <!-- Transmission is important to link the joints and the controller (see rb_theron_control/config/rb_theron_control.yaml)-->
  <transmission name="robot_right_wheel_joint_trans">
    <type>transmission_interface/SimpleTransmission</type>
    <joint name="robot_right_wheel_joint">
      <!-- for the gazebo plugin -->
      <!--hardwareInterface>EffortJointInterface</hardwareInterface-->
      <!-- for ros control controller -->
      <hardwareInterface>hardware_interface/VelocityJointInterface</hardwareInterface>
    </joint>
    <actuator name="robot_right_wheel_joint_motor">
      <mechanicalReduction>1</mechanicalReduction>
      <motorTorqueConstant>20</motorTorqueConstant>
    </actuator>
  </transmission>
  <gazebo reference="robot_right_wheel_link">
    <!-- mu1 value="5.0"/>
			<mu2 value="0.5"/>
			<kp value="10000000.0" />
			<kd value="1.0" />
			<fdir1 value="1 0 0"/>
			<material>Gazebo/Yellow</material>
			<turnGravityOff>false</turnGravityOff -->
    <!-- mu1 value="5.0"/>
			<mu2 value="0.5"/ -->
    <mu1 value="1.0"/>
    <mu2 value="1.0"/>
    <!-- kp value="100000.0" / -->
    <kp value="10000000.0"/>
    <kd value="1.0"/>
    <!-- fdir1 value="1 0 0"/ -->
    <material>Gazebo/Yellow</material>
    <turnGravityOff>false</turnGravityOff>
    <!--kp>500000.0</kp>
			<kd>10.0</kd>
			<mu1>10</mu1>
			<mu2>10</mu2>
			<fdir1>1 0 0</fdir1-->
    <!--minDepth>0.001</minDepth-->
    <!--material>Gazebo/Black</material-->
    <!--mu1 value="10"/>
			<mu2 value="5"/>
			<kp value="500000.0" />
			<kd value="10.0" />
			<fdir1 value="1 0 0"/>
			<material>Gazebo/Yellow</material>
			<turnGravityOff>false</turnGravityOff-->
  </gazebo>
  <gazebo reference="robot_right_wheel_tire_link">
    <material>Gazebo/Gray</material>
    <turnGravityOff>false</turnGravityOff>
  </gazebo>
  <!--gazebo reference="${name}_wheel_link">
			<kp>500000.0</kp>
			<kd>10.0</kd>
			<mu1>10</mu1>
			<mu2>10</mu2>
			<fdir1>1 0 0</fdir1>
			<maxVel>1.0</maxVel>
			<minDepth>0.003</minDepth>
			<material>Gazebo/Yellow</material>
			<turnGravityOff>false</turnGravityOff>
			<implicitSpringDamper>1</implicitSpringDamper>
		</gazebo-->
  <!--WHEEL TIRE -->
  <joint name="robot_left_wheel_joint" type="continuous">
    <parent link="robot_base_link"/>
    <child link="robot_left_wheel_link"/>
    <origin rpy="0 0 0" xyz="0 0.2516 0.0"/>
    <axis rpy="0 0 0" xyz="0 1 0"/>
    <limit effort="100" velocity="100"/>
    <joint_properties damping="0.0" friction="0.0"/>
  </joint>
  <link name="robot_left_wheel_link">
    <visual>
      <!-- HIGH RESOLUTION WHEELS -->
      <!-- LOW RESOLUTION WHEELS -->
      <origin rpy="1.5707963267948966 0 0" xyz="0 0 0"/>
      <geometry>
        <cylinder length="0.025" radius="0.0762"/>
      </geometry>
    </visual>
    <collision>
      <origin rpy="1.5707963267948966 0 0" xyz="0 0 0"/>
      <geometry>
        <cylinder length="0.025" radius="0.0762"/>
      </geometry>
    </collision>
    <inertial>
      <mass value="1"/>
      <origin rpy="3.141592653589793 0 0" xyz="0 0 0"/>
      <inertia ixx="0.0015036933333333335" ixy="0" ixz="0" iyy="0.0015036933333333335" iyz="0" izz="0.00290322"/>
    </inertial>
  </link>
  <joint name="robot_left_wheel_tire_joint" type="fixed">
    <parent link="robot_left_wheel_link"/>
    <child link="robot_left_wheel_tire_link"/>
    <origin rpy="0 0 0" xyz="0 0 0"/>
  </joint>
  <link name="robot_left_wheel_tire_link">
    <visual>
      <origin rpy="1.5707963267948966 0 0" xyz="0 0 0"/>
      <geometry>
        <cylinder length="0.026000000000000002" radius="0.070104"/>
      </geometry>
    </visual>
  </link>
  <!-- Transmission is important to link the joints and the controller (see rb_theron_control/config/rb_theron_control.yaml)-->
  <transmission name="robot_left_wheel_joint_trans">
    <type>transmission_interface/SimpleTransmission</type>
    <joint name="robot_left_wheel_joint">
      <!-- for the gazebo plugin -->
      <!--hardwareInterface>EffortJointInterface</hardwareInterface-->
      <!-- for ros control controller -->
      <hardwareInterface>hardware_interface/VelocityJointInterface</hardwareInterface>
    </joint>
    <actuator name="robot_left_wheel_joint_motor">
      <mechanicalReduction>1</mechanicalReduction>
      <motorTorqueConstant>20</motorTorqueConstant>
    </actuator>
  </transmission>
  <gazebo reference="robot_left_wheel_link">
    <!-- mu1 value="5.0"/>
			<mu2 value="0.5"/>
			<kp value="10000000.0" />
			<kd value="1.0" />
			<fdir1 value="1 0 0"/>
			<material>Gazebo/Yellow</material>
			<turnGravityOff>false</turnGravityOff -->
    <!-- mu1 value="5.0"/>
			<mu2 value="0.5"/ -->
    <mu1 value="1.0"/>
    <mu2 value="1.0"/>
    <!-- kp value="100000.0" / -->
    <kp value="10000000.0"/>
    <kd value="1.0"/>
    <!-- fdir1 value="1 0 0"/ -->
    <material>Gazebo/Yellow</material>
    <turnGravityOff>false</turnGravityOff>
    <!--kp>500000.0</kp>
			<kd>10.0</kd>
			<mu1>10</mu1>
			<mu2>10</mu2>
			<fdir1>1 0 0</fdir1-->
    <!--minDepth>0.001</minDepth-->
    <!--material>Gazebo/Black</material-->
    <!--mu1 value="10"/>
			<mu2 value="5"/>
			<kp value="500000.0" />
			<kd value="10.0" />
			<fdir1 value="1 0 0"/>
			<material>Gazebo/Yellow</material>
			<turnGravityOff>false</turnGravityOff-->
  </gazebo>
  <gazebo reference="robot_left_wheel_tire_link">
    <material>Gazebo/Gray</material>
    <turnGravityOff>false</turnGravityOff>
  </gazebo>
  <!--gazebo reference="${name}_wheel_link">
			<kp>500000.0</kp>
			<kd>10.0</kd>
			<mu1>10</mu1>
			<mu2>10</mu2>
			<fdir1>1 0 0</fdir1>
			<maxVel>1.0</maxVel>
			<minDepth>0.003</minDepth>
			<material>Gazebo/Yellow</material>
			<turnGravityOff>false</turnGravityOff>
			<implicitSpringDamper>1</implicitSpringDamper>
		</gazebo-->
  <joint name="robot_front_left_joint_support" type="continuous">
    <parent link="robot_base_link"/>
    <child link="robot_front_left_support"/>
    <origin rpy="0 0 0" xyz="0.235 0.1825 0.0448"/>
    <axis rpy="0 3.141592653589793 0" xyz="0 0 1"/>
    <limit effort="100" velocity="100"/>
    <dynamics damping="0.8" friction="0.01"/>
  </joint>
  <link name="robot_front_left_support">
    <visual>
      <origin rpy="0 0 0" xyz="0 0 0"/>
      <geometry>
        <mesh filename="package://robot_description/meshes/wheels/caster_wheel/caster_wheel.stl"/>
      </geometry>
    </visual>
    <inertial>
      <mass value="1.5"/>
      <origin xyz="0 0 0"/>
      <inertia ixx="4.9999999999999996e-05" ixy="0" ixz="0" iyy="4.9999999999999996e-05" iyz="0" izz="7.5e-05"/>
      <!--Check these values -->
    </inertial>
  </link>
  <joint name="robot_front_left_joint_wheel" type="continuous">
    <parent link="robot_front_left_support"/>
    <child link="robot_front_left_wheel"/>
    <origin rpy="0 0 0" xyz="-0.033 0.0 -0.071"/>
    <axis rpy="0 0 0" xyz="0 1 0"/>
    <limit effort="100" velocity="100"/>
    <joint_properties damping="0.2" friction="2.0"/>
  </joint>
  <link name="robot_front_left_wheel">
    <visual>
      <origin rpy="1.5707963267948966 0 0" xyz="0 0 0"/>
      <geometry>
        <cylinder length="0.025" radius="0.05"/>
      </geometry>
    </visual>
    <collision>
      <origin rpy="1.5707963267948966 0 0" xyz="0 0 0"/>
      <geometry>
        <cylinder length="0.025" radius="0.05"/>
      </geometry>
      <surface>
        <bounce restitution_coefficient="0.5"/>
      </surface>
    </collision>
    <inertial>
      <mass value="0.25"/>
      <origin xyz="0 0 0"/>
      <inertia ixx="0.00016927083333333337" ixy="0" ixz="0" iyy="0.00016927083333333337" iyz="0" izz="0.00031250000000000006"/>
    </inertial>
  </link>
  <transmission name="robot_front_left_support_joint_trans">
    <type>transmission_interface/SimpleTransmission</type>
    <joint name="robot_front_left_joint_support">
      <hardwareInterface>hardware_interface/EffortJointInterface</hardwareInterface>
    </joint>
    <actuator name="robot_front_left_support_joint_motor">
      <mechanicalReduction>1</mechanicalReduction>
      <motorTorqueConstant>1</motorTorqueConstant>
    </actuator>
  </transmission>
  <transmission name="robot_front_left_wheel_joint_trans">
    <type>transmission_interface/SimpleTransmission</type>
    <joint name="robot_front_left_joint_wheel">
      <hardwareInterface>hardware_interface/EffortJointInterface</hardwareInterface>
    </joint>
    <actuator name="robot_front_left_wheel_joint_motor">
      <mechanicalReduction>1</mechanicalReduction>
      <motorTorqueConstant>1</motorTorqueConstant>
    </actuator>
  </transmission>
  <gazebo reference="robot_front_left_support">
    <mu1 value="5.0"/>
    <mu2 value="0.5"/>
    <kp value="10000000.0"/>
    <kd value="1.0"/>
    <fdir1 value="1 0 0"/>
    <turnGravityOff>false</turnGravityOff>
  </gazebo>
  <gazebo reference="robot_front_left_wheel">
    <mu1 value="100.0"/>
    <mu2 value="100.0"/>
    <!-- kp value="10000000.0" / -->
    <kp value="100000.0"/>
    <kd value="100.0"/>
    <!-- fdir1 value="1 0 0"/ -->
    <material>Gazebo/Black</material>
    <turnGravityOff>false</turnGravityOff>
  </gazebo>
  <joint name="robot_front_right_joint_support" type="continuous">
    <parent link="robot_base_link"/>
    <child link="robot_front_right_support"/>
    <origin rpy="0 0 0" xyz="0.235 -0.1825 0.0448"/>
    <axis rpy="0 3.141592653589793 0" xyz="0 0 1"/>
    <limit effort="100" velocity="100"/>
    <dynamics damping="0.8" friction="0.01"/>
  </joint>
  <link name="robot_front_right_support">
    <visual>
      <origin rpy="0 0 0" xyz="0 0 0"/>
      <geometry>
        <mesh filename="package://robot_description/meshes/wheels/caster_wheel/caster_wheel.stl"/>
      </geometry>
    </visual>
    <inertial>
      <mass value="1.5"/>
      <origin xyz="0 0 0"/>
      <inertia ixx="4.9999999999999996e-05" ixy="0" ixz="0" iyy="4.9999999999999996e-05" iyz="0" izz="7.5e-05"/>
      <!--Check these values -->
    </inertial>
  </link>
  <joint name="robot_front_right_joint_wheel" type="continuous">
    <parent link="robot_front_right_support"/>
    <child link="robot_front_right_wheel"/>
    <origin rpy="0 0 0" xyz="-0.033 0.0 -0.071"/>
    <axis rpy="0 0 0" xyz="0 1 0"/>
    <limit effort="100" velocity="100"/>
    <joint_properties damping="0.2" friction="2.0"/>
  </joint>
  <link name="robot_front_right_wheel">
    <visual>
      <origin rpy="1.5707963267948966 0 0" xyz="0 0 0"/>
      <geometry>
        <cylinder length="0.025" radius="0.05"/>
      </geometry>
    </visual>
    <collision>
      <origin rpy="1.5707963267948966 0 0" xyz="0 0 0"/>
      <geometry>
        <cylinder length="0.025" radius="0.05"/>
      </geometry>
      <surface>
        <bounce restitution_coefficient="0.5"/>
      </surface>
    </collision>
    <inertial>
      <mass value="0.25"/>
      <origin xyz="0 0 0"/>
      <inertia ixx="0.00016927083333333337" ixy="0" ixz="0" iyy="0.00016927083333333337" iyz="0" izz="0.00031250000000000006"/>
    </inertial>
  </link>
  <transmission name="robot_front_right_support_joint_trans">
    <type>transmission_interface/SimpleTransmission</type>
    <joint name="robot_front_right_joint_support">
      <hardwareInterface>hardware_interface/EffortJointInterface</hardwareInterface>
    </joint>
    <actuator name="robot_front_right_support_joint_motor">
      <mechanicalReduction>1</mechanicalReduction>
      <motorTorqueConstant>1</motorTorqueConstant>
    </actuator>
  </transmission>
  <transmission name="robot_front_right_wheel_joint_trans">
    <type>transmission_interface/SimpleTransmission</type>
    <joint name="robot_front_right_joint_wheel">
      <hardwareInterface>hardware_interface/EffortJointInterface</hardwareInterface>
    </joint>
    <actuator name="robot_front_right_wheel_joint_motor">
      <mechanicalReduction>1</mechanicalReduction>
      <motorTorqueConstant>1</motorTorqueConstant>
    </actuator>
  </transmission>
  <gazebo reference="robot_front_right_support">
    <mu1 value="5.0"/>
    <mu2 value="0.5"/>
    <kp value="10000000.0"/>
    <kd value="1.0"/>
    <fdir1 value="1 0 0"/>
    <turnGravityOff>false</turnGravityOff>
  </gazebo>
  <gazebo reference="robot_front_right_wheel">
    <mu1 value="100.0"/>
    <mu2 value="100.0"/>
    <!-- kp value="10000000.0" / -->
    <kp value="100000.0"/>
    <kd value="100.0"/>
    <!-- fdir1 value="1 0 0"/ -->
    <material>Gazebo/Black</material>
    <turnGravityOff>false</turnGravityOff>
  </gazebo>
  <joint name="robot_rear_left_joint_support" type="continuous">
    <parent link="robot_base_link"/>
    <child link="robot_rear_left_support"/>
    <origin rpy="0 0 0" xyz="-0.235 0.1825 0.0448"/>
    <axis rpy="0 3.141592653589793 0" xyz="0 0 1"/>
    <limit effort="100" velocity="100"/>
    <dynamics damping="0.8" friction="0.01"/>
  </joint>
  <link name="robot_rear_left_support">
    <visual>
      <origin rpy="0 0 0" xyz="0 0 0"/>
      <geometry>
        <mesh filename="package://robot_description/meshes/wheels/caster_wheel/caster_wheel.stl"/>
      </geometry>
    </visual>
    <inertial>
      <mass value="1.5"/>
      <origin xyz="0 0 0"/>
      <inertia ixx="4.9999999999999996e-05" ixy="0" ixz="0" iyy="4.9999999999999996e-05" iyz="0" izz="7.5e-05"/>
      <!--Check these values -->
    </inertial>
  </link>
  <joint name="robot_rear_left_joint_wheel" type="continuous">
    <parent link="robot_rear_left_support"/>
    <child link="robot_rear_left_wheel"/>
    <origin rpy="0 0 0" xyz="-0.033 0.0 -0.071"/>
    <axis rpy="0 0 0" xyz="0 1 0"/>
    <limit effort="100" velocity="100"/>
    <joint_properties damping="0.2" friction="2.0"/>
  </joint>
  <link name="robot_rear_left_wheel">
    <visual>
      <origin rpy="1.5707963267948966 0 0" xyz="0 0 0"/>
      <geometry>
        <cylinder length="0.025" radius="0.05"/>
      </geometry>
    </visual>
    <collision>
      <origin rpy="1.5707963267948966 0 0" xyz="0 0 0"/>
      <geometry>
        <cylinder length="0.025" radius="0.05"/>
      </geometry>
      <surface>
        <bounce restitution_coefficient="0.5"/>
      </surface>
    </collision>
    <inertial>
      <mass value="0.25"/>
      <origin xyz="0 0 0"/>
      <inertia ixx="0.00016927083333333337" ixy="0" ixz="0" iyy="0.00016927083333333337" iyz="0" izz="0.00031250000000000006"/>
    </inertial>
  </link>
  <transmission name="robot_rear_left_support_joint_trans">
    <type>transmission_interface/SimpleTransmission</type>
    <joint name="robot_rear_left_joint_support">
      <hardwareInterface>hardware_interface/EffortJointInterface</hardwareInterface>
    </joint>
    <actuator name="robot_rear_left_support_joint_motor">
      <mechanicalReduction>1</mechanicalReduction>
      <motorTorqueConstant>1</motorTorqueConstant>
    </actuator>
  </transmission>
  <transmission name="robot_rear_left_wheel_joint_trans">
    <type>transmission_interface/SimpleTransmission</type>
    <joint name="robot_rear_left_joint_wheel">
      <hardwareInterface>hardware_interface/EffortJointInterface</hardwareInterface>
    </joint>
    <actuator name="robot_rear_left_wheel_joint_motor">
      <mechanicalReduction>1</mechanicalReduction>
      <motorTorqueConstant>1</motorTorqueConstant>
    </actuator>
  </transmission>
  <gazebo reference="robot_rear_left_support">
    <mu1 value="5.0"/>
    <mu2 value="0.5"/>
    <kp value="10000000.0"/>
    <kd value="1.0"/>
    <fdir1 value="1 0 0"/>
    <turnGravityOff>false</turnGravityOff>
  </gazebo>
  <gazebo reference="robot_rear_left_wheel">
    <mu1 value="100.0"/>
    <mu2 value="100.0"/>
    <!-- kp value="10000000.0" / -->
    <kp value="100000.0"/>
    <kd value="100.0"/>
    <!-- fdir1 value="1 0 0"/ -->
    <material>Gazebo/Black</material>
    <turnGravityOff>false</turnGravityOff>
  </gazebo>
  <joint name="robot_rear_right_joint_support" type="continuous">
    <parent link="robot_base_link"/>
    <child link="robot_rear_right_support"/>
    <origin rpy="0 0 0" xyz="-0.235 -0.1825 0.0448"/>
    <axis rpy="0 3.141592653589793 0" xyz="0 0 1"/>
    <limit effort="100" velocity="100"/>
    <dynamics damping="0.8" friction="0.01"/>
  </joint>
  <link name="robot_rear_right_support">
    <visual>
      <origin rpy="0 0 0" xyz="0 0 0"/>
      <geometry>
        <mesh filename="package://robot_description/meshes/wheels/caster_wheel/caster_wheel.stl"/>
      </geometry>
    </visual>
    <inertial>
      <mass value="1.5"/>
      <origin xyz="0 0 0"/>
      <inertia ixx="4.9999999999999996e-05" ixy="0" ixz="0" iyy="4.9999999999999996e-05" iyz="0" izz="7.5e-05"/>
      <!--Check these values -->
    </inertial>
  </link>
  <joint name="robot_rear_right_joint_wheel" type="continuous">
    <parent link="robot_rear_right_support"/>
    <child link="robot_rear_right_wheel"/>
    <origin rpy="0 0 0" xyz="-0.033 0.0 -0.071"/>
    <axis rpy="0 0 0" xyz="0 1 0"/>
    <limit effort="100" velocity="100"/>
    <joint_properties damping="0.2" friction="2.0"/>
  </joint>
  <link name="robot_rear_right_wheel">
    <visual>
      <origin rpy="1.5707963267948966 0 0" xyz="0 0 0"/>
      <geometry>
        <cylinder length="0.025" radius="0.05"/>
      </geometry>
    </visual>
    <collision>
      <origin rpy="1.5707963267948966 0 0" xyz="0 0 0"/>
      <geometry>
        <cylinder length="0.025" radius="0.05"/>
      </geometry>
      <surface>
        <bounce restitution_coefficient="0.5"/>
      </surface>
    </collision>
    <inertial>
      <mass value="0.25"/>
      <origin xyz="0 0 0"/>
      <inertia ixx="0.00016927083333333337" ixy="0" ixz="0" iyy="0.00016927083333333337" iyz="0" izz="0.00031250000000000006"/>
    </inertial>
  </link>
  <transmission name="robot_rear_right_support_joint_trans">
    <type>transmission_interface/SimpleTransmission</type>
    <joint name="robot_rear_right_joint_support">
      <hardwareInterface>hardware_interface/EffortJointInterface</hardwareInterface>
    </joint>
    <actuator name="robot_rear_right_support_joint_motor">
      <mechanicalReduction>1</mechanicalReduction>
      <motorTorqueConstant>1</motorTorqueConstant>
    </actuator>
  </transmission>
  <transmission name="robot_rear_right_wheel_joint_trans">
    <type>transmission_interface/SimpleTransmission</type>
    <joint name="robot_rear_right_joint_wheel">
      <hardwareInterface>hardware_interface/EffortJointInterface</hardwareInterface>
    </joint>
    <actuator name="robot_rear_right_wheel_joint_motor">
      <mechanicalReduction>1</mechanicalReduction>
      <motorTorqueConstant>1</motorTorqueConstant>
    </actuator>
  </transmission>
  <gazebo reference="robot_rear_right_support">
    <mu1 value="5.0"/>
    <mu2 value="0.5"/>
    <kp value="10000000.0"/>
    <kd value="1.0"/>
    <fdir1 value="1 0 0"/>
    <turnGravityOff>false</turnGravityOff>
  </gazebo>
  <gazebo reference="robot_rear_right_wheel">
    <mu1 value="100.0"/>
    <mu2 value="100.0"/>
    <!-- kp value="10000000.0" / -->
    <kp value="100000.0"/>
    <kd value="100.0"/>
    <!-- fdir1 value="1 0 0"/ -->
    <material>Gazebo/Black</material>
    <turnGravityOff>false</turnGravityOff>
  </gazebo>
  <joint name="robot_vectornav_base_joint" type="fixed">
    <origin rpy="0 0 0" xyz="-0.1975 0.0 0.1598"/>
    <parent link="robot_base_link"/>
    <child link="robot_vectornav_base_link"/>
  </joint>
  <link name="robot_vectornav_base_link">
    <inertial>
      <origin rpy="0 0 0" xyz="0.0 0 0.01"/>
      <mass value="0.05"/>
      <inertia ixx="3.3333333333333337e-06" ixy="0" ixz="0" iyy="3.3333333333333337e-06" iyz="0" izz="3.3333333333333337e-06"/>
    </inertial>
    <visual>
      <origin rpy="0 0 0" xyz="0 0 0"/>
      <material name="vectornav_imu_color">
        <color rgba="1 0 0 1"/>
      </material>
      <geometry>
        <mesh filename="package://robotnik_sensors/meshes/imu/vectornav_vn100.stl"/>
      </geometry>
    </visual>
    <collision>
      <origin rpy="0 0 0" xyz="0 0 0.0045"/>
      <geometry>
        <box size="0.036 0.037 0.009"/>
      </geometry>
    </collision>
  </link>
  <joint name="robot_vectornav_joint" type="fixed">
    <axis xyz="1 0 0"/>
    <origin xyz="-0.00745 0.0 0.0088"/>
    <parent link="robot_vectornav_base_link"/>
    <child link="robot_vectornav_link"/>
  </joint>
  <link name="robot_vectornav_link"/>
  <gazebo reference="robot_vectornav_link">
    <gravity>true</gravity>
    <sensor name="imu_sensor" type="imu">
      <always_on>true</always_on>
      <update_rate>200.0</update_rate>
      <visualize>true</visualize>
      <imu>
        <orientation>
          <x>
            <noise type="gaussian">
              <mean>0.0</mean>
              <!-- <stddev>2e-3</stddev> -->
              <stddev>0.01</stddev>
            </noise>
          </x>
          <y>
            <noise type="gaussian">
              <mean>0.0</mean>
              <!-- <stddev>2e-3</stddev> -->
              <stddev>0.01</stddev>
            </noise>
          </y>
          <z>
            <noise type="gaussian">
              <mean>0.0</mean>
              <!-- <stddev>2e-3</stddev> -->
              <stddev>0.01</stddev>
            </noise>
          </z>
        </orientation>
        <angular_velocity>
          <x>
            <noise type="gaussian">
              <mean>0.0</mean>
              <!-- <stddev>2e-4</stddev> -->
              <stddev>0.01</stddev>
            </noise>
          </x>
          <y>
            <noise type="gaussian">
              <mean>0.0</mean>
              <!-- <stddev>2e-4</stddev> -->
              <stddev>0.01</stddev>
            </noise>
          </y>
          <z>
            <noise type="gaussian">
              <mean>0.0</mean>
              <!-- <stddev>2e-3</stddev> -->
              <stddev>0.01</stddev>
            </noise>
          </z>
        </angular_velocity>
        <linear_acceleration>
          <x>
            <noise type="gaussian">
              <mean>0.0</mean>
              <!-- <stddev>1.7e-2</stddev> -->
              <stddev>0.01</stddev>
            </noise>
          </x>
          <y>
            <noise type="gaussian">
              <mean>0.0</mean>
              <!-- <stddev>1.7e-2</stddev> -->
              <stddev>0.01</stddev>
            </noise>
          </y>
          <z>
            <noise type="gaussian">
              <mean>0.0</mean>
              <!-- <stddev>1.7e-2</stddev> -->
              <stddev>0.01</stddev>
            </noise>
          </z>
        </linear_acceleration>
      </imu>
      <plugin filename="libgazebo_ros_imu_sensor.so" name="imu">
        <ros>
          <namespace>robot</namespace>
          <remapping>~/out:=imu/data</remapping>
        </ros>
        <initial_orientation_as_reference>false</initial_orientation_as_reference>
        <frame_name>robot_vectornav_link</frame_name>
      </plugin>
    </sensor>
  </gazebo>
  <gazebo reference="robot_vectornav_base_link">
    <material>Gazebo/Red</material>
  </gazebo>
  <joint name="robot_front_laser_base_joint" type="fixed">
    <origin rpy="0 -3.141592653589793 2.356194490192345" xyz="0.2675 -0.215 0.1613"/>
    <parent link="robot_base_link"/>
    <child link="robot_front_laser_base_link"/>
  </joint>
  <link name="robot_front_laser_base_link">
    <collision>
      <origin rpy="0 0 0" xyz="0 0 0.036"/>
      <geometry>
        <cylinder length="0.072" radius="0.022"/>
      </geometry>
    </collision>
    <visual>
      <origin rpy="0 0 0" xyz="0 0 0"/>
      <geometry>
        <mesh filename="package://robotnik_sensors/meshes/hokuyo_ust_20lx.dae"/>
      </geometry>
    </visual>
    <inertial>
      <origin rpy="0 0 0" xyz="0.0 0 0.036"/>
      <mass value="0.130"/>
      <inertia ixx="8.016666666666669e-05" ixy="0" ixz="0" iyy="8.016666666666669e-05" iyz="0" izz="5.4166666666666685e-05"/>
    </inertial>
  </link>
  <joint name="robot_front_laser_joint" type="fixed">
    <parent link="robot_front_laser_base_link"/>
    <child link="robot_front_laser_link"/>
    <origin rpy="0 0 0" xyz="0.00 0.0 0.0474"/>
  </joint>
  <link name="robot_front_laser_link"/>
  <gazebo reference="robot_front_laser_link">
    <sensor name="robot_front_laser_sensor" type="ray">
      <pose>0 0 0 0 0 0</pose>
      <visualize>false</visualize>
      <update_rate>40</update_rate>
      <ray>
        <scan>
          <horizontal>
            <samples>1081</samples>
            <resolution>1</resolution>
            <min_angle>-2.3562</min_angle>
            <max_angle>2.3562</max_angle>
          </horizontal>
        </scan>
        <range>
          <min>0.06</min>
          <max>20.0</max>
          <resolution>0.004359297</resolution>
        </range>
        <noise>
          <type>gaussian</type>
          <mean>0.0</mean>
          <stddev>0.01</stddev>
        </noise>
      </ray>
      <plugin filename="libgazebo_ros_ray_sensor.so" name="front_laser">
        <ros>
          <namespace>robot</namespace>
          <remapping>~/out:=~/scan</remapping>
        </ros>
        <output_type>sensor_msgs/LaserScan</output_type>
        <frame_name>robot_front_laser_link</frame_name>
      </plugin>
    </sensor>
  </gazebo>
  <joint name="robot_rear_laser_base_joint" type="fixed">
    <origin rpy="0 -3.141592653589793 -0.7853981633974483" xyz="-0.2675 0.215 0.1613"/>
    <parent link="robot_base_link"/>
    <child link="robot_rear_laser_base_link"/>
  </joint>
  <link name="robot_rear_laser_base_link">
    <collision>
      <origin rpy="0 0 0" xyz="0 0 0.036"/>
      <geometry>
        <cylinder length="0.072" radius="0.022"/>
      </geometry>
    </collision>
    <visual>
      <origin rpy="0 0 0" xyz="0 0 0"/>
      <geometry>
        <mesh filename="package://robotnik_sensors/meshes/hokuyo_ust_20lx.dae"/>
      </geometry>
    </visual>
    <inertial>
      <origin rpy="0 0 0" xyz="0.0 0 0.036"/>
      <mass value="0.130"/>
      <inertia ixx="8.016666666666669e-05" ixy="0" ixz="0" iyy="8.016666666666669e-05" iyz="0" izz="5.4166666666666685e-05"/>
    </inertial>
  </link>
  <joint name="robot_rear_laser_joint" type="fixed">
    <parent link="robot_rear_laser_base_link"/>
    <child link="robot_rear_laser_link"/>
    <origin rpy="0 0 0" xyz="0.00 0.0 0.0474"/>
  </joint>
  <link name="robot_rear_laser_link"/>
  <gazebo reference="robot_rear_laser_link">
    <sensor name="robot_rear_laser_sensor" type="ray">
      <pose>0 0 0 0 0 0</pose>
      <visualize>false</visualize>
      <update_rate>40</update_rate>
      <ray>
        <scan>
          <horizontal>
            <samples>1081</samples>
            <resolution>1</resolution>
            <min_angle>-2.3562</min_angle>
            <max_angle>2.3562</max_angle>
          </horizontal>
        </scan>
        <range>
          <min>0.06</min>
          <max>20.0</max>
          <resolution>0.004359297</resolution>
        </range>
        <noise>
          <type>gaussian</type>
          <mean>0.0</mean>
          <stddev>0.01</stddev>
        </noise>
      </ray>
      <plugin filename="libgazebo_ros_ray_sensor.so" name="rear_laser">
        <ros>
          <namespace>robot</namespace>
          <remapping>~/out:=~/scan</remapping>
        </ros>
        <output_type>sensor_msgs/LaserScan</output_type>
        <frame_name>robot_rear_laser_link</frame_name>
      </plugin>
    </sensor>
  </gazebo>
  <joint name="robot_front_rgbd_camera_base_joint" type="fixed">
    <origin rpy="0 0 0" xyz="0.3045 0.0 0.1898"/>
    <parent link="robot_base_link"/>
    <child link="robot_front_rgbd_camera_base_link"/>
  </joint>
  <link name="robot_front_rgbd_camera_base_link"/>
  <!-- camera body, with origin at bottom screw mount -->
  <joint name="robot_front_rgbd_camera_joint" type="fixed">
    <parent link="robot_front_rgbd_camera_base_link"/>
    <child link="robot_front_rgbd_camera_link"/>
    <origin rpy="0 0 0" xyz="0.01 0.02 0"/>
    <child link="robot_front_rgbd_camera_link"/>
  </joint>
  <link name="robot_front_rgbd_camera_link">
    <!-- camera link is aligned with the infrared sensor 1 that is "in the middle of the camera", not the one in the edge -->
    <visual>
      <origin rpy="1.5707963267948966 0 1.5707963267948966" xyz="0.0149 -0.0175 0"/>
      <geometry>
        <!-- <box size="${d435_cam_width} ${d435_cam_height} ${d435_cam_depth}"/> -->
        <mesh filename="package://robotnik_sensors/meshes/depth/intel_realsense_d435/intel_d435_color.dae"/>
      </geometry>
    </visual>
    <collision>
      <origin rpy="0 0 0" xyz="0 -0.0175 0"/>
      <geometry>
        <box size="0.02505 0.09 0.025"/>
      </geometry>
    </collision>
    <inertial>
      <origin rpy="0 0 0" xyz="0.0025 -0.015 0.0"/>
      <mass value="0.1"/>
      <inertia ixx="7.270833333333333e-05" ixy="0" ixz="0" iyy="1.041666666666667e-05" iyz="0" izz="7.270833333333333e-05"/>
    </inertial>
  </link>
  <!-- Use the nominal extrinsics between camera frames if the calibrated extrinsics aren't being published. e.g. running the device in simulation  -->
  <!-- camera depth joints and links -->
  <joint name="robot_front_rgbd_camera_depth_joint" type="fixed">
    <origin rpy="0 0 0" xyz="0 0 0"/>
    <parent link="robot_front_rgbd_camera_link"/>
    <child link="robot_front_rgbd_camera_depth_frame"/>
  </joint>
  <link name="robot_front_rgbd_camera_depth_frame"/>
  <joint name="robot_front_rgbd_camera_depth_optical_joint" type="fixed">
    <origin rpy="-1.5707963267948966 0 -1.5707963267948966" xyz="0 0 0"/>
    <parent link="robot_front_rgbd_camera_depth_frame"/>
    <child link="robot_front_rgbd_camera_depth_optical_frame"/>
  </joint>
  <link name="robot_front_rgbd_camera_depth_optical_frame"/>
  <!-- camera left IR joints and links -->
  <joint name="robot_front_rgbd_camera_infra1_joint" type="fixed">
    <origin rpy="0 0 0" xyz="0 0.0 0"/>
    <parent link="robot_front_rgbd_camera_link"/>
    <child link="robot_front_rgbd_camera_infra1_frame"/>
  </joint>
  <link name="robot_front_rgbd_camera_infra1_frame"/>
  <joint name="robot_front_rgbd_camera_infra1_optical_joint" type="fixed">
    <origin rpy="-1.5707963267948966 0 -1.5707963267948966" xyz="0 0 0"/>
    <parent link="robot_front_rgbd_camera_infra1_frame"/>
    <child link="robot_front_rgbd_camera_infra1_optical_frame"/>
  </joint>
  <link name="robot_front_rgbd_camera_infra1_optical_frame"/>
  <!-- camera right IR joints and links -->
  <joint name="robot_front_rgbd_camera_infra2_joint" type="fixed">
    <origin rpy="0 0 0" xyz="0 -0.05 0"/>
    <parent link="robot_front_rgbd_camera_link"/>
    <child link="robot_front_rgbd_camera_infra2_frame"/>
  </joint>
  <link name="robot_front_rgbd_camera_infra2_frame"/>
  <joint name="robot_front_rgbd_camera_infra2_optical_joint" type="fixed">
    <origin rpy="-1.5707963267948966 0 -1.5707963267948966" xyz="0 0 0"/>
    <parent link="robot_front_rgbd_camera_infra2_frame"/>
    <child link="robot_front_rgbd_camera_infra2_optical_frame"/>
  </joint>
  <link name="robot_front_rgbd_camera_infra2_optical_frame"/>
  <!-- camera color joints and links -->
  <joint name="robot_front_rgbd_camera_color_joint" type="fixed">
    <origin rpy="0 0 0" xyz="0 0.015 0"/>
    <parent link="robot_front_rgbd_camera_link"/>
    <child link="robot_front_rgbd_camera_color_frame"/>
  </joint>
  <link name="robot_front_rgbd_camera_color_frame"/>
  <joint name="robot_front_rgbd_camera_color_optical_joint" type="fixed">
    <origin rpy="-1.5707963267948966 0 -1.5707963267948966" xyz="0 0 0"/>
    <parent link="robot_front_rgbd_camera_color_frame"/>
    <child link="robot_front_rgbd_camera_color_optical_frame"/>
  </joint>
  <link name="robot_front_rgbd_camera_color_optical_frame"/>
  <gazebo reference="robot_front_rgbd_camera_color_frame">
    <sensor name="front_camera_color" type="camera">
      <camera name="front_camera_color">
        <horizontal_fov>1.0471975511965976</horizontal_fov>
        <vertical_fov>0.5235987755982988</vertical_fov>
        <image>
          <width>640</width>
          <height>480</height>
          <format>RGB_INT8</format>
        </image>
        <clip>
          <near>0.1</near>
          <far>100</far>
        </clip>
        <noise>
          <type>gaussian</type>
          <mean>0.0</mean>
          <stddev>0.05</stddev>
        </noise>
      </camera>
      <always_on>1</always_on>
      <update_rate>5</update_rate>
      <visualize>false</visualize>
      <plugin filename="libgazebo_ros_camera.so" name="front_camera_color">
        <ros>
          <namespace>robot/front_camera_color</namespace>
        </ros>
        <camera_name>front_camera_color</camera_name>
        <frame_name>robot_front_rgbd_camera_color_optical_frame</frame_name>
      </plugin>
    </sensor>
  </gazebo>
  <gazebo reference="robot_front_rgbd_camera_infra2_frame">
    <sensor name="front_camera_irred1" type="camera">
      <camera name="front_camera_irred1">
        <horizontal_fov>1.0471975511965976</horizontal_fov>
        <vertical_fov>0.5235987755982988</vertical_fov>
        <image>
          <width>640</width>
          <height>480</height>
          <format>L_INT8</format>
        </image>
        <clip>
          <near>0.1</near>
          <far>100</far>
        </clip>
        <noise>
          <type>gaussian</type>
          <mean>0.0</mean>
          <stddev>0.05</stddev>
        </noise>
      </camera>
      <always_on>1</always_on>
      <update_rate>5</update_rate>
      <visualize>false</visualize>
      <plugin filename="libgazebo_ros_camera.so" name="front_camera_irred1">
        <ros>
          <namespace>robot/front_camera_irred1</namespace>
        </ros>
        <camera_name>front_camera_irred1</camera_name>
        <frame_name>robot_front_rgbd_camera_infra1_optical_frame</frame_name>
      </plugin>
    </sensor>
  </gazebo>
  <gazebo reference="robot_front_rgbd_camera_infra2_frame">
    <sensor name="front_camera_irred2" type="camera">
      <camera name="front_camera_irred2">
        <horizontal_fov>1.0471975511965976</horizontal_fov>
        <vertical_fov>0.5235987755982988</vertical_fov>
        <image>
          <width>640</width>
          <height>480</height>
          <format>L_INT8</format>
        </image>
        <clip>
          <near>0.1</near>
          <far>100</far>
        </clip>
        <noise>
          <type>gaussian</type>
          <mean>0.0</mean>
          <stddev>0.05</stddev>
        </noise>
      </camera>
      <always_on>1</always_on>
      <update_rate>5</update_rate>
      <visualize>false</visualize>
      <plugin filename="libgazebo_ros_camera.so" name="front_camera_irred2">
        <ros>
          <namespace>robot/front_camera_irred2</namespace>
        </ros>
        <camera_name>front_camera_irred2</camera_name>
        <frame_name>robot_front_rgbd_camera_infra2_optical_frame</frame_name>
      </plugin>
    </sensor>
  </gazebo>
  <gazebo reference="robot_front_rgbd_camera_depth_frame">
    <sensor name="front_camera_depth" type="depth">
      <pose>0.0 0.0 0.0 0.0 0.0 0.0</pose>
      <visualize>false</visualize>
      <update_rate>5</update_rate>
      <camera>
        <horizontal_fov>1.0471975511965976</horizontal_fov>
        <vertical_fov>0.5235987755982988</vertical_fov>
        <image>
          <width>640</width>
          <height>480</height>
          <format>B8G8R8</format>
        </image>
        <clip>
          <near>0.1</near>
          <far>100</far>
        </clip>
        <noise>
          <type>gaussian</type>
          <mean>0.0</mean>
          <stddev>0.007</stddev>
        </noise>
      </camera>
      <plugin filename="libgazebo_ros_camera.so" name="front_camera_depth">
        <ros>
          <namespace>robot</namespace>
          <remapping>~/image_raw:=~/_depthrgb/image_raw_color</remapping>
          <remapping>~/camera_info:=~/_depthrgb/camera_info</remapping>
          <remapping>~/points:=~/_depthpoint_cloud/cloud_registered</remapping>
          <remapping>~/depth/camera_info:=~/_depthdepth/camera_info</remapping>
          <remapping>~/depth/image_raw:=~/_depthdepth/depth_registered</remapping>
        </ros>
        <camera_name>front_camera_depth</camera_name>
        <frame_name>robot_front_rgbd_camera_depth_optical_frame</frame_name>
        <min_depth>0.1</min_depth>
        <max_depth>100</max_depth>
      </plugin>
    </sensor>
  </gazebo>
  <joint name="robot_rear_rgbd_camera_base_joint" type="fixed">
    <origin rpy="0 0 3.141592653589793" xyz="-0.3045 0.0 0.1158"/>
    <parent link="robot_base_link"/>
    <child link="robot_rear_rgbd_camera_base_link"/>
  </joint>
  <link name="robot_rear_rgbd_camera_base_link"/>
  <!-- camera body, with origin at bottom screw mount -->
  <joint name="robot_rear_rgbd_camera_joint" type="fixed">
    <parent link="robot_rear_rgbd_camera_base_link"/>
    <child link="robot_rear_rgbd_camera_link"/>
    <origin rpy="0 0 0" xyz="0.01 0.02 0"/>
    <child link="robot_rear_rgbd_camera_link"/>
  </joint>
  <link name="robot_rear_rgbd_camera_link">
    <!-- camera link is aligned with the infrared sensor 1 that is "in the middle of the camera", not the one in the edge -->
    <visual>
      <origin rpy="1.5707963267948966 0 1.5707963267948966" xyz="0.0149 -0.0175 0"/>
      <geometry>
        <!-- <box size="${d435_cam_width} ${d435_cam_height} ${d435_cam_depth}"/> -->
        <mesh filename="package://robotnik_sensors/meshes/depth/intel_realsense_d435/intel_d435_color.dae"/>
      </geometry>
    </visual>
    <collision>
      <origin rpy="0 0 0" xyz="0 -0.0175 0"/>
      <geometry>
        <box size="0.02505 0.09 0.025"/>
      </geometry>
    </collision>
    <inertial>
      <origin rpy="0 0 0" xyz="0.0025 -0.015 0.0"/>
      <mass value="0.1"/>
      <inertia ixx="7.270833333333333e-05" ixy="0" ixz="0" iyy="1.041666666666667e-05" iyz="0" izz="7.270833333333333e-05"/>
    </inertial>
  </link>
  <!-- Use the nominal extrinsics between camera frames if the calibrated extrinsics aren't being published. e.g. running the device in simulation  -->
  <!-- camera depth joints and links -->
  <joint name="robot_rear_rgbd_camera_depth_joint" type="fixed">
    <origin rpy="0 0 0" xyz="0 0 0"/>
    <parent link="robot_rear_rgbd_camera_link"/>
    <child link="robot_rear_rgbd_camera_depth_frame"/>
  </joint>
  <link name="robot_rear_rgbd_camera_depth_frame"/>
  <joint name="robot_rear_rgbd_camera_depth_optical_joint" type="fixed">
    <origin rpy="-1.5707963267948966 0 -1.5707963267948966" xyz="0 0 0"/>
    <parent link="robot_rear_rgbd_camera_depth_frame"/>
    <child link="robot_rear_rgbd_camera_depth_optical_frame"/>
  </joint>
  <link name="robot_rear_rgbd_camera_depth_optical_frame"/>
  <!-- camera left IR joints and links -->
  <joint name="robot_rear_rgbd_camera_infra1_joint" type="fixed">
    <origin rpy="0 0 0" xyz="0 0.0 0"/>
    <parent link="robot_rear_rgbd_camera_link"/>
    <child link="robot_rear_rgbd_camera_infra1_frame"/>
  </joint>
  <link name="robot_rear_rgbd_camera_infra1_frame"/>
  <joint name="robot_rear_rgbd_camera_infra1_optical_joint" type="fixed">
    <origin rpy="-1.5707963267948966 0 -1.5707963267948966" xyz="0 0 0"/>
    <parent link="robot_rear_rgbd_camera_infra1_frame"/>
    <child link="robot_rear_rgbd_camera_infra1_optical_frame"/>
  </joint>
  <link name="robot_rear_rgbd_camera_infra1_optical_frame"/>
  <!-- camera right IR joints and links -->
  <joint name="robot_rear_rgbd_camera_infra2_joint" type="fixed">
    <origin rpy="0 0 0" xyz="0 -0.05 0"/>
    <parent link="robot_rear_rgbd_camera_link"/>
    <child link="robot_rear_rgbd_camera_infra2_frame"/>
  </joint>
  <link name="robot_rear_rgbd_camera_infra2_frame"/>
  <joint name="robot_rear_rgbd_camera_infra2_optical_joint" type="fixed">
    <origin rpy="-1.5707963267948966 0 -1.5707963267948966" xyz="0 0 0"/>
    <parent link="robot_rear_rgbd_camera_infra2_frame"/>
    <child link="robot_rear_rgbd_camera_infra2_optical_frame"/>
  </joint>
  <link name="robot_rear_rgbd_camera_infra2_optical_frame"/>
  <!-- camera color joints and links -->
  <joint name="robot_rear_rgbd_camera_color_joint" type="fixed">
    <origin rpy="0 0 0" xyz="0 0.015 0"/>
    <parent link="robot_rear_rgbd_camera_link"/>
    <child link="robot_rear_rgbd_camera_color_frame"/>
  </joint>
  <link name="robot_rear_rgbd_camera_color_frame"/>
  <joint name="robot_rear_rgbd_camera_color_optical_joint" type="fixed">
    <origin rpy="-1.5707963267948966 0 -1.5707963267948966" xyz="0 0 0"/>
    <parent link="robot_rear_rgbd_camera_color_frame"/>
    <child link="robot_rear_rgbd_camera_color_optical_frame"/>
  </joint>
  <link name="robot_rear_rgbd_camera_color_optical_frame"/>
  <gazebo reference="robot_rear_rgbd_camera_color_frame">
    <sensor name="rear_camera_color" type="camera">
      <camera name="rear_camera_color">
        <horizontal_fov>1.0471975511965976</horizontal_fov>
        <vertical_fov>0.5235987755982988</vertical_fov>
        <image>
          <width>640</width>
          <height>480</height>
          <format>RGB_INT8</format>
        </image>
        <clip>
          <near>0.1</near>
          <far>100</far>
        </clip>
        <noise>
          <type>gaussian</type>
          <mean>0.0</mean>
          <stddev>0.05</stddev>
        </noise>
      </camera>
      <always_on>1</always_on>
      <update_rate>5</update_rate>
      <visualize>false</visualize>
      <plugin filename="libgazebo_ros_camera.so" name="rear_camera_color">
        <ros>
          <namespace>robot/rear_camera_color</namespace>
        </ros>
        <camera_name>rear_camera_color</camera_name>
        <frame_name>robot_rear_rgbd_camera_color_optical_frame</frame_name>
      </plugin>
    </sensor>
  </gazebo>
  <gazebo reference="robot_rear_rgbd_camera_infra2_frame">
    <sensor name="rear_camera_irred1" type="camera">
      <camera name="rear_camera_irred1">
        <horizontal_fov>1.0471975511965976</horizontal_fov>
        <vertical_fov>0.5235987755982988</vertical_fov>
        <image>
          <width>640</width>
          <height>480</height>
          <format>L_INT8</format>
        </image>
        <clip>
          <near>0.1</near>
          <far>100</far>
        </clip>
        <noise>
          <type>gaussian</type>
          <mean>0.0</mean>
          <stddev>0.05</stddev>
        </noise>
      </camera>
      <always_on>1</always_on>
      <update_rate>5</update_rate>
      <visualize>false</visualize>
      <plugin filename="libgazebo_ros_camera.so" name="rear_camera_irred1">
        <ros>
          <namespace>robot/rear_camera_irred1</namespace>
        </ros>
        <camera_name>rear_camera_irred1</camera_name>
        <frame_name>robot_rear_rgbd_camera_infra1_optical_frame</frame_name>
      </plugin>
    </sensor>
  </gazebo>
  <gazebo reference="robot_rear_rgbd_camera_infra2_frame">
    <sensor name="rear_camera_irred2" type="camera">
      <camera name="rear_camera_irred2">
        <horizontal_fov>1.0471975511965976</horizontal_fov>
        <vertical_fov>0.5235987755982988</vertical_fov>
        <image>
          <width>640</width>
          <height>480</height>
          <format>L_INT8</format>
        </image>
        <clip>
          <near>0.1</near>
          <far>100</far>
        </clip>
        <noise>
          <type>gaussian</type>
          <mean>0.0</mean>
          <stddev>0.05</stddev>
        </noise>
      </camera>
      <always_on>1</always_on>
      <update_rate>5</update_rate>
      <visualize>false</visualize>
      <plugin filename="libgazebo_ros_camera.so" name="rear_camera_irred2">
        <ros>
          <namespace>robot/rear_camera_irred2</namespace>
        </ros>
        <camera_name>rear_camera_irred2</camera_name>
        <frame_name>robot_rear_rgbd_camera_infra2_optical_frame</frame_name>
      </plugin>
    </sensor>
  </gazebo>
  <gazebo reference="robot_rear_rgbd_camera_depth_frame">
    <sensor name="rear_camera_depth" type="depth">
      <pose>0.0 0.0 0.0 0.0 0.0 0.0</pose>
      <visualize>false</visualize>
      <update_rate>5</update_rate>
      <camera>
        <horizontal_fov>1.0471975511965976</horizontal_fov>
        <vertical_fov>0.5235987755982988</vertical_fov>
        <image>
          <width>640</width>
          <height>480</height>
          <format>B8G8R8</format>
        </image>
        <clip>
          <near>0.1</near>
          <far>100</far>
        </clip>
        <noise>
          <type>gaussian</type>
          <mean>0.0</mean>
          <stddev>0.007</stddev>
        </noise>
      </camera>
      <plugin filename="libgazebo_ros_camera.so" name="rear_camera_depth">
        <ros>
          <namespace>robot</namespace>
          <remapping>~/image_raw:=~/_depthrgb/image_raw_color</remapping>
          <remapping>~/camera_info:=~/_depthrgb/camera_info</remapping>
          <remapping>~/points:=~/_depthpoint_cloud/cloud_registered</remapping>
          <remapping>~/depth/camera_info:=~/_depthdepth/camera_info</remapping>
          <remapping>~/depth/image_raw:=~/_depthdepth/depth_registered</remapping>
        </ros>
        <camera_name>rear_camera_depth</camera_name>
        <frame_name>robot_rear_rgbd_camera_depth_optical_frame</frame_name>
        <min_depth>0.1</min_depth>
        <max_depth>100</max_depth>
      </plugin>
    </sensor>
  </gazebo>
  <gazebo>
    <plugin filename="libgazebo_ros2_control.so" name="ros_control">
      <robot_param>robot_description</robot_param>
      <robot_param_node>robot_state_publisher</robot_param_node>
      <parameters>/home/joel/Documentos/GitHub/Robotnik_practicas/Robotnik_ws/install/robot_description/share/robot_description/simulators/gazebo_classic/rbtheron/rbtheron_controller_params.yaml</parameters>
      <ros>
        <namespace>/robot</namespace>
      </ros>
    </plugin>
  </gazebo>
  <ros2_control name="GazeboSystem" type="system">
    <hardware>
      <plugin>gazebo_ros2_control/GazeboSystem</plugin>
    </hardware>
    <joint name="robot_left_wheel_joint">
      <command_interface name="velocity">
        <param name="min">-10</param>
        <param name="max">10</param>
      </command_interface>
      <state_interface name="position"/>
      <state_interface name="velocity"/>
      <state_interface name="effort"/>
    </joint>
    <joint name="robot_right_wheel_joint">
      <command_interface name="velocity">
        <param name="min">-10</param>
        <param name="max">10</param>
      </command_interface>
      <state_interface name="position"/>
      <state_interface name="velocity"/>
      <state_interface name="effort"/>
    </joint>
  </ros2_control>
  <gazebo>
    <plugin filename="libgazebo_ros_planar_move.so" name="planar_move">
      <ros>
        <!-- Remap the default topic -->
        <remapping>cmd_vel:=/robot/robotnik_base_controller/cmd_vel</remapping>
      </ros>
      <update_rate>100</update_rate>
      <publish_rate>10</publish_rate>
      <!-- output -->
      <publish_odom>true</publish_odom>
      <publish_odom_tf>true</publish_odom_tf>
      <odometry_frame>robot_odom</odometry_frame>
      <robot_base_frame>robot_base_footprint</robot_base_frame>
    </plugin>
  </gazebo>
</robot>
