<?xml version="1.0" ?>
<!-- =================================================================================== -->
<!-- |    This document was autogenerated by xacro from rbrobout.urdf.xacro            | -->
<!-- |    EDITING THIS FILE BY HAND IS NOT RECOMMENDED                                 | -->
<!-- =================================================================================== -->
<robot name="rbrobout">
  <!-- ***************** -->
  <!-- Imported elements -->
  <!-- ***************** -->
  <!-- Import all posible elements defined in the urdf.xacro files. All these elements are defined as macro:xacros -->
  <!-- ***************** -->
  <!-- Imported elements -->
  <!-- ***************** -->
  <!-- First we import all posible elements defined in the urdf.xacro files. All these elements are defined as macro:xacros -->
  <!-- in kg-->
  <!-- This file unifies all sensors that can be used on simulation, defined as xacro:macros -->
  <!-- source en.wikipedia.org/wiki/List_of_moments_of_inertia-->
  <!-- $(find robotnik_sensors_gazebo)/config/camera/axis_m5013.yaml -->
  <!-- $(find robotnik_sensors_gazebo)/config/camera/axis_m5074.yaml-->
  <!-- $(find robotnik_sensors_gazebo)/config/camera/axis_m5525.yaml -->
  <!--$(find robotnik_sensors_gazebo)/config/camera/axis_m5526.yaml-->
  <!-- This file unifies all sensors that can be used on simulation, defined as xacro:macros -->
  <!-- source en.wikipedia.org/wiki/List_of_moments_of_inertia-->
  <!-- $(find robotnik_sensors_gazebo)/config/camera/axis_m5013.yaml -->
  <!-- $(find robotnik_sensors_gazebo)/config/camera/axis_m5074.yaml-->
  <!-- $(find robotnik_sensors_gazebo)/config/camera/axis_m5525.yaml -->
  <!--$(find robotnik_sensors_gazebo)/config/camera/axis_m5526.yaml-->
  <!-- Properties and Arguments -->
  <!-- *************** -->
  <!-- Robots Elements -->
  <!-- *************** -->
  <!-- Here we create the robot elements using the xacro:macros imported at the beggining of this file -->
  <!-- BASE FOOTPRINT -->
  <link name="robot_base_footprint">
    <visual>
      <origin rpy="0 0 0" xyz="0 0 0"/>
      <geometry>
        <box size="0.001 0.001 0.001"/>
      </geometry>
    </visual>
  </link>
  <joint name="robot_base_footprint_joint" type="fixed">
    <origin rpy="0 0 0" xyz="0 0 0.127"/>
    <!-- ${wheel_radius} property must be defined inside wheel description -->
    <parent link="robot_base_footprint"/>
    <child link="robot_base_link"/>
  </joint>
  <!-- BASE_LINK -->
  <link name="robot_base_link">
    <inertial>
      <mass value="200.0"/>
      <origin xyz="0 0 0.10"/>
      <inertia ixx="38.166666666666664" ixy="0" ixz="0" iyy="67.33333333333333" iyz="0" izz="104.16666666666667"/>
    </inertial>
    <visual>
      <origin rpy="0 0 0" xyz="0 0 0"/>
      <geometry>
        <mesh filename="package://robot_description/meshes/bases/rbrobout/robout_chassis.stl"/>
      </geometry>
      <material name="darkgrey">
        <color rgba="0.1 0.1 0.1 1"/>
      </material>
    </visual>
    <collision>
      <origin rpy="0 0 0 " xyz="0 0 0"/>
      <geometry>
        <mesh filename="package://robot_description/meshes/bases/rbrobout/robout_chassis.stl"/>
      </geometry>
    </collision>
  </link>
  <!-- DOCKING CONTACTS -->
  <!-- <joint name="${prefix}base_docking_joint" type="fixed">
            <origin xyz="0.284 0.012 0.068" rpy="0 0 0 " />
            <parent link="${prefix}base_link"/>
            <child link="${prefix}base_docking_contact_link" />
        </joint> -->
  <!-- DOCKING LINK -->
  <!-- <link name="${prefix}base_docking_contact_link" /> -->
  <joint name="robot_front_right_wheel_joint" type="continuous">
    <parent link="robot_base_link"/>
    <child link="robot_front_right_wheel_link"/>
    <origin rpy="0 0 0" xyz="0.558 -0.2865 0.0"/>
    <axis rpy="0 0 0" xyz="0 1 0"/>
    <limit effort="100" velocity="100"/>
    <joint_properties damping="0.5" friction="2.0"/>
  </joint>
  <link name="robot_front_right_wheel_link">
    <visual>
      <origin rpy="1.570796326795 0 0" xyz="0 0 0"/>
      <geometry>
        <mesh filename="package://robot_description/meshes/wheels/omni_wheel/robout_wheel.stl"/>
      </geometry>
      <material name="darkgrey">
        <color rgba="0.2 0.2 0.2 1"/>
      </material>
    </visual>
    <collision>
      <origin rpy="1.570796326795 0 0" xyz="0 0 0"/>
      <geometry>
        <cylinder length="0.087" radius="0.127"/>
      </geometry>
    </collision>
    <inertial>
      <mass value="6.5"/>
      <origin xyz="0 0 0"/>
      <inertia ixx="0.0303095" ixy="0" ixz="0" iyy="0.05241925" iyz="0" izz="0.0303095"/>
    </inertial>
  </link>
  <gazebo reference="robot_front_right_wheel_link">
    <mu1>0.90</mu1>
    <mu2>0.85</mu2>
    <kp>2.75e6</kp>
    <kd>8.25e1</kd>
    <fdir1>0 0 0</fdir1>
  </gazebo>
  <joint name="robot_front_left_wheel_joint" type="continuous">
    <parent link="robot_base_link"/>
    <child link="robot_front_left_wheel_link"/>
    <origin rpy="0 0 0" xyz="0.558 0.2865 0.0"/>
    <axis rpy="0 0 0" xyz="0 1 0"/>
    <limit effort="100" velocity="100"/>
    <joint_properties damping="0.5" friction="2.0"/>
  </joint>
  <link name="robot_front_left_wheel_link">
    <visual>
      <origin rpy="1.570796326795 0 0" xyz="0 0 0"/>
      <geometry>
        <mesh filename="package://robot_description/meshes/wheels/omni_wheel/robout_wheel.stl"/>
      </geometry>
      <material name="darkgrey">
        <color rgba="0.2 0.2 0.2 1"/>
      </material>
    </visual>
    <collision>
      <origin rpy="1.570796326795 0 0" xyz="0 0 0"/>
      <geometry>
        <cylinder length="0.087" radius="0.127"/>
      </geometry>
    </collision>
    <inertial>
      <mass value="6.5"/>
      <origin xyz="0 0 0"/>
      <inertia ixx="0.0303095" ixy="0" ixz="0" iyy="0.05241925" iyz="0" izz="0.0303095"/>
    </inertial>
  </link>
  <gazebo reference="robot_front_left_wheel_link">
    <mu1>0.90</mu1>
    <mu2>0.85</mu2>
    <kp>2.75e6</kp>
    <kd>8.25e1</kd>
    <fdir1>0 0 0</fdir1>
  </gazebo>
  <joint name="robot_back_left_wheel_joint" type="continuous">
    <parent link="robot_base_link"/>
    <child link="robot_back_left_wheel_link"/>
    <origin rpy="0 0 0" xyz="-0.558 0.2865 0.0"/>
    <axis rpy="0 0 0" xyz="0 1 0"/>
    <limit effort="100" velocity="100"/>
    <joint_properties damping="0.5" friction="2.0"/>
  </joint>
  <link name="robot_back_left_wheel_link">
    <visual>
      <origin rpy="1.570796326795 0 0" xyz="0 0 0"/>
      <geometry>
        <mesh filename="package://robot_description/meshes/wheels/omni_wheel/robout_wheel.stl"/>
      </geometry>
      <material name="darkgrey">
        <color rgba="0.2 0.2 0.2 1"/>
      </material>
    </visual>
    <collision>
      <origin rpy="1.570796326795 0 0" xyz="0 0 0"/>
      <geometry>
        <cylinder length="0.087" radius="0.127"/>
      </geometry>
    </collision>
    <inertial>
      <mass value="6.5"/>
      <origin xyz="0 0 0"/>
      <inertia ixx="0.0303095" ixy="0" ixz="0" iyy="0.05241925" iyz="0" izz="0.0303095"/>
    </inertial>
  </link>
  <gazebo reference="robot_back_left_wheel_link">
    <mu1>0.90</mu1>
    <mu2>0.85</mu2>
    <kp>2.75e6</kp>
    <kd>8.25e1</kd>
    <fdir1>0 0 0</fdir1>
  </gazebo>
  <joint name="robot_back_right_wheel_joint" type="continuous">
    <parent link="robot_base_link"/>
    <child link="robot_back_right_wheel_link"/>
    <origin rpy="0 0 0" xyz="-0.558 -0.2865 0.0"/>
    <axis rpy="0 0 0" xyz="0 1 0"/>
    <limit effort="100" velocity="100"/>
    <joint_properties damping="0.5" friction="2.0"/>
  </joint>
  <link name="robot_back_right_wheel_link">
    <visual>
      <origin rpy="1.570796326795 0 0" xyz="0 0 0"/>
      <geometry>
        <mesh filename="package://robot_description/meshes/wheels/omni_wheel/robout_wheel.stl"/>
      </geometry>
      <material name="darkgrey">
        <color rgba="0.2 0.2 0.2 1"/>
      </material>
    </visual>
    <collision>
      <origin rpy="1.570796326795 0 0" xyz="0 0 0"/>
      <geometry>
        <cylinder length="0.087" radius="0.127"/>
      </geometry>
    </collision>
    <inertial>
      <mass value="6.5"/>
      <origin xyz="0 0 0"/>
      <inertia ixx="0.0303095" ixy="0" ixz="0" iyy="0.05241925" iyz="0" izz="0.0303095"/>
    </inertial>
  </link>
  <gazebo reference="robot_back_right_wheel_link">
    <mu1>0.90</mu1>
    <mu2>0.85</mu2>
    <kp>2.75e6</kp>
    <kd>8.25e1</kd>
    <fdir1>0 0 0</fdir1>
  </gazebo>
  <joint name="robot_vectornav_base_joint" type="fixed">
    <origin rpy="0 0 0" xyz="0.242 -0.053 -0.028"/>
    <parent link="robot_base_link"/>
    <child link="robot_vectornav_base_link"/>
  </joint>
  <link name="robot_vectornav_base_link">
    <inertial>
      <origin rpy="0 0 0" xyz="0.0 0 0.01"/>
      <mass value="0.05"/>
      <inertia ixx="3.3333333333333337e-06" ixy="0" ixz="0" iyy="3.3333333333333337e-06" iyz="0" izz="3.3333333333333337e-06"/>
    </inertial>
    <visual>
      <origin rpy="0 0 0" xyz="0 0 0"/>
      <material name="vectornav_imu_color">
        <color rgba="1 0 0 1"/>
      </material>
      <geometry>
        <mesh filename="package://robotnik_sensors/meshes/imu/vectornav_vn100.stl"/>
      </geometry>
    </visual>
    <collision>
      <origin rpy="0 0 0" xyz="0 0 0.0045"/>
      <geometry>
        <box size="0.036 0.037 0.009"/>
      </geometry>
    </collision>
  </link>
  <joint name="robot_vectornav_joint" type="fixed">
    <axis xyz="1 0 0"/>
    <origin xyz="-0.00745 0.0 0.0088"/>
    <parent link="robot_vectornav_base_link"/>
    <child link="robot_vectornav_link"/>
  </joint>
  <link name="robot_vectornav_link"/>
  <gazebo reference="robot_vectornav_base_link">
    <material>Gazebo/Red</material>
  </gazebo>
  <joint name="robot_front_rgbd_camera_base_joint" type="fixed">
    <origin rpy="0 0 0" xyz="0.835 0.0 0.1555"/>
    <parent link="robot_base_link"/>
    <child link="robot_front_rgbd_camera_base_link"/>
  </joint>
  <link name="robot_front_rgbd_camera_base_link"/>
  <!-- camera body, with origin at bottom screw mount -->
  <joint name="robot_front_rgbd_camera_joint" type="fixed">
    <parent link="robot_front_rgbd_camera_base_link"/>
    <child link="robot_front_rgbd_camera_link"/>
    <origin rpy="0 0 0" xyz="0.01 0.02 0"/>
    <child link="robot_front_rgbd_camera_link"/>
  </joint>
  <link name="robot_front_rgbd_camera_link">
    <!-- camera link is aligned with the infrared sensor 1 that is "in the middle of the camera", not the one in the edge -->
    <visual>
      <origin rpy="1.5707963267948966 0 1.5707963267948966" xyz="0.0149 -0.0175 0"/>
      <geometry>
        <!-- <box size="${d435_cam_width} ${d435_cam_height} ${d435_cam_depth}"/> -->
        <mesh filename="package://robotnik_sensors/meshes/depth/intel_realsense_d435/intel_d435_color.dae"/>
      </geometry>
    </visual>
    <collision>
      <origin rpy="0 0 0" xyz="0 -0.0175 0"/>
      <geometry>
        <box size="0.02505 0.09 0.025"/>
      </geometry>
    </collision>
    <inertial>
      <origin rpy="0 0 0" xyz="0.0025 -0.015 0.0"/>
      <mass value="0.1"/>
      <inertia ixx="7.270833333333333e-05" ixy="0" ixz="0" iyy="1.041666666666667e-05" iyz="0" izz="7.270833333333333e-05"/>
    </inertial>
  </link>
  <!-- Use the nominal extrinsics between camera frames if the calibrated extrinsics aren't being published. e.g. running the device in simulation  -->
  <!-- camera depth joints and links -->
  <joint name="robot_front_rgbd_camera_depth_joint" type="fixed">
    <origin rpy="0 0 0" xyz="0 0 0"/>
    <parent link="robot_front_rgbd_camera_link"/>
    <child link="robot_front_rgbd_camera_depth_frame"/>
  </joint>
  <link name="robot_front_rgbd_camera_depth_frame"/>
  <joint name="robot_front_rgbd_camera_depth_optical_joint" type="fixed">
    <origin rpy="-1.5707963267948966 0 -1.5707963267948966" xyz="0 0 0"/>
    <parent link="robot_front_rgbd_camera_depth_frame"/>
    <child link="robot_front_rgbd_camera_depth_optical_frame"/>
  </joint>
  <link name="robot_front_rgbd_camera_depth_optical_frame"/>
  <!-- camera left IR joints and links -->
  <joint name="robot_front_rgbd_camera_infra1_joint" type="fixed">
    <origin rpy="0 0 0" xyz="0 0.0 0"/>
    <parent link="robot_front_rgbd_camera_link"/>
    <child link="robot_front_rgbd_camera_infra1_frame"/>
  </joint>
  <link name="robot_front_rgbd_camera_infra1_frame"/>
  <joint name="robot_front_rgbd_camera_infra1_optical_joint" type="fixed">
    <origin rpy="-1.5707963267948966 0 -1.5707963267948966" xyz="0 0 0"/>
    <parent link="robot_front_rgbd_camera_infra1_frame"/>
    <child link="robot_front_rgbd_camera_infra1_optical_frame"/>
  </joint>
  <link name="robot_front_rgbd_camera_infra1_optical_frame"/>
  <!-- camera right IR joints and links -->
  <joint name="robot_front_rgbd_camera_infra2_joint" type="fixed">
    <origin rpy="0 0 0" xyz="0 -0.05 0"/>
    <parent link="robot_front_rgbd_camera_link"/>
    <child link="robot_front_rgbd_camera_infra2_frame"/>
  </joint>
  <link name="robot_front_rgbd_camera_infra2_frame"/>
  <joint name="robot_front_rgbd_camera_infra2_optical_joint" type="fixed">
    <origin rpy="-1.5707963267948966 0 -1.5707963267948966" xyz="0 0 0"/>
    <parent link="robot_front_rgbd_camera_infra2_frame"/>
    <child link="robot_front_rgbd_camera_infra2_optical_frame"/>
  </joint>
  <link name="robot_front_rgbd_camera_infra2_optical_frame"/>
  <!-- camera color joints and links -->
  <joint name="robot_front_rgbd_camera_color_joint" type="fixed">
    <origin rpy="0 0 0" xyz="0 0.015 0"/>
    <parent link="robot_front_rgbd_camera_link"/>
    <child link="robot_front_rgbd_camera_color_frame"/>
  </joint>
  <link name="robot_front_rgbd_camera_color_frame"/>
  <joint name="robot_front_rgbd_camera_color_optical_joint" type="fixed">
    <origin rpy="-1.5707963267948966 0 -1.5707963267948966" xyz="0 0 0"/>
    <parent link="robot_front_rgbd_camera_color_frame"/>
    <child link="robot_front_rgbd_camera_color_optical_frame"/>
  </joint>
  <link name="robot_front_rgbd_camera_color_optical_frame"/>
  <joint name="robot_rear_rgbd_camera_base_joint" type="fixed">
    <origin rpy="0 3.14159265359 0" xyz="-0.835 0.0 0.1555"/>
    <parent link="robot_base_link"/>
    <child link="robot_rear_rgbd_camera_base_link"/>
  </joint>
  <link name="robot_rear_rgbd_camera_base_link"/>
  <!-- camera body, with origin at bottom screw mount -->
  <joint name="robot_rear_rgbd_camera_joint" type="fixed">
    <parent link="robot_rear_rgbd_camera_base_link"/>
    <child link="robot_rear_rgbd_camera_link"/>
    <origin rpy="0 0 0" xyz="0.01 0.02 0"/>
    <child link="robot_rear_rgbd_camera_link"/>
  </joint>
  <link name="robot_rear_rgbd_camera_link">
    <!-- camera link is aligned with the infrared sensor 1 that is "in the middle of the camera", not the one in the edge -->
    <visual>
      <origin rpy="1.5707963267948966 0 1.5707963267948966" xyz="0.0149 -0.0175 0"/>
      <geometry>
        <!-- <box size="${d435_cam_width} ${d435_cam_height} ${d435_cam_depth}"/> -->
        <mesh filename="package://robotnik_sensors/meshes/depth/intel_realsense_d435/intel_d435_color.dae"/>
      </geometry>
    </visual>
    <collision>
      <origin rpy="0 0 0" xyz="0 -0.0175 0"/>
      <geometry>
        <box size="0.02505 0.09 0.025"/>
      </geometry>
    </collision>
    <inertial>
      <origin rpy="0 0 0" xyz="0.0025 -0.015 0.0"/>
      <mass value="0.1"/>
      <inertia ixx="7.270833333333333e-05" ixy="0" ixz="0" iyy="1.041666666666667e-05" iyz="0" izz="7.270833333333333e-05"/>
    </inertial>
  </link>
  <!-- Use the nominal extrinsics between camera frames if the calibrated extrinsics aren't being published. e.g. running the device in simulation  -->
  <!-- camera depth joints and links -->
  <joint name="robot_rear_rgbd_camera_depth_joint" type="fixed">
    <origin rpy="0 0 0" xyz="0 0 0"/>
    <parent link="robot_rear_rgbd_camera_link"/>
    <child link="robot_rear_rgbd_camera_depth_frame"/>
  </joint>
  <link name="robot_rear_rgbd_camera_depth_frame"/>
  <joint name="robot_rear_rgbd_camera_depth_optical_joint" type="fixed">
    <origin rpy="-1.5707963267948966 0 -1.5707963267948966" xyz="0 0 0"/>
    <parent link="robot_rear_rgbd_camera_depth_frame"/>
    <child link="robot_rear_rgbd_camera_depth_optical_frame"/>
  </joint>
  <link name="robot_rear_rgbd_camera_depth_optical_frame"/>
  <!-- camera left IR joints and links -->
  <joint name="robot_rear_rgbd_camera_infra1_joint" type="fixed">
    <origin rpy="0 0 0" xyz="0 0.0 0"/>
    <parent link="robot_rear_rgbd_camera_link"/>
    <child link="robot_rear_rgbd_camera_infra1_frame"/>
  </joint>
  <link name="robot_rear_rgbd_camera_infra1_frame"/>
  <joint name="robot_rear_rgbd_camera_infra1_optical_joint" type="fixed">
    <origin rpy="-1.5707963267948966 0 -1.5707963267948966" xyz="0 0 0"/>
    <parent link="robot_rear_rgbd_camera_infra1_frame"/>
    <child link="robot_rear_rgbd_camera_infra1_optical_frame"/>
  </joint>
  <link name="robot_rear_rgbd_camera_infra1_optical_frame"/>
  <!-- camera right IR joints and links -->
  <joint name="robot_rear_rgbd_camera_infra2_joint" type="fixed">
    <origin rpy="0 0 0" xyz="0 -0.05 0"/>
    <parent link="robot_rear_rgbd_camera_link"/>
    <child link="robot_rear_rgbd_camera_infra2_frame"/>
  </joint>
  <link name="robot_rear_rgbd_camera_infra2_frame"/>
  <joint name="robot_rear_rgbd_camera_infra2_optical_joint" type="fixed">
    <origin rpy="-1.5707963267948966 0 -1.5707963267948966" xyz="0 0 0"/>
    <parent link="robot_rear_rgbd_camera_infra2_frame"/>
    <child link="robot_rear_rgbd_camera_infra2_optical_frame"/>
  </joint>
  <link name="robot_rear_rgbd_camera_infra2_optical_frame"/>
  <!-- camera color joints and links -->
  <joint name="robot_rear_rgbd_camera_color_joint" type="fixed">
    <origin rpy="0 0 0" xyz="0 0.015 0"/>
    <parent link="robot_rear_rgbd_camera_link"/>
    <child link="robot_rear_rgbd_camera_color_frame"/>
  </joint>
  <link name="robot_rear_rgbd_camera_color_frame"/>
  <joint name="robot_rear_rgbd_camera_color_optical_joint" type="fixed">
    <origin rpy="-1.5707963267948966 0 -1.5707963267948966" xyz="0 0 0"/>
    <parent link="robot_rear_rgbd_camera_color_frame"/>
    <child link="robot_rear_rgbd_camera_color_optical_frame"/>
  </joint>
  <link name="robot_rear_rgbd_camera_color_optical_frame"/>
  <joint name="robot_front_laser_base_joint" type="fixed">
    <origin rpy="0 0 0.7853981633975" xyz="0.8 0.3666 -0.06"/>
    <parent link="robot_base_link"/>
    <child link="robot_front_laser_base_link"/>
  </joint>
  <link name="robot_front_laser_base_link">
    <visual>
      <origin rpy="0 0 0" xyz="0 0 0"/>
      <geometry>
        <mesh filename="package://robotnik_sensors/meshes/2d_lidar/sick/microscan3.dae"/>
      </geometry>
    </visual>
    <collision>
      <origin rpy="0 0 0" xyz="0 0 0"/>
      <geometry>
        <mesh filename="package://robotnik_sensors/meshes/2d_lidar/sick/microscan3.dae"/>
      </geometry>
    </collision>
    <inertial>
      <mass value="1.15"/>
      <origin rpy="0 0 0" xyz="0 0 0.075"/>
      <inertia ixx="0.0033370124999999996" ixy="0" ixz="0" iyy="0.003358383333333333" iyz="0" izz="0.0023828958333333332"/>
    </inertial>
  </link>
  <joint name="robot_front_laser_joint" type="fixed">
    <origin rpy="0 0 0" xyz="0.0 0 0.110"/>
    <parent link="robot_front_laser_base_link"/>
    <child link="robot_front_laser_link"/>
  </joint>
  <link name="robot_front_laser_link"/>
  <joint name="robot_rear_laser_base_joint" type="fixed">
    <origin rpy="0 0 -2.3561944901925003" xyz="-0.8 -0.3666 -0.06"/>
    <parent link="robot_base_link"/>
    <child link="robot_rear_laser_base_link"/>
  </joint>
  <link name="robot_rear_laser_base_link">
    <visual>
      <origin rpy="0 0 0" xyz="0 0 0"/>
      <geometry>
        <mesh filename="package://robotnik_sensors/meshes/2d_lidar/sick/microscan3.dae"/>
      </geometry>
    </visual>
    <collision>
      <origin rpy="0 0 0" xyz="0 0 0"/>
      <geometry>
        <mesh filename="package://robotnik_sensors/meshes/2d_lidar/sick/microscan3.dae"/>
      </geometry>
    </collision>
    <inertial>
      <mass value="1.15"/>
      <origin rpy="0 0 0" xyz="0 0 0.075"/>
      <inertia ixx="0.0033370124999999996" ixy="0" ixz="0" iyy="0.003358383333333333" iyz="0" izz="0.0023828958333333332"/>
    </inertial>
  </link>
  <joint name="robot_rear_laser_joint" type="fixed">
    <origin rpy="0 0 0" xyz="0.0 0 0.110"/>
    <parent link="robot_rear_laser_base_link"/>
    <child link="robot_rear_laser_link"/>
  </joint>
  <link name="robot_rear_laser_link"/>
  <ros2_control name="robout" type="system">
    <hardware>
      <plugin>robotnik_base_hw/RobotnikBaseHW</plugin>
      <param name="device">can0</param>
      <param name="sync_hz">50</param>
    </hardware>
    <joint name="robot_front_left_wheel_joint">
      <param name="id">0x01</param>
      <param name="encoder_resolution">4000</param>
      <param name="gearbox_ratio">9.56</param>
      <param name="spin">1</param>
      <command_interface name="position">
        <param name="min">0.0</param>
        <param name="max">0.0</param>
      </command_interface>
      <command_interface name="velocity">
        <param name="min">-18.8495</param>
        <param name="max">18.8495</param>
      </command_interface>
      <command_interface name="effort">
        <param name="min">-50</param>
        <param name="max">50</param>
      </command_interface>
      <state_interface name="position"/>
      <state_interface name="velocity"/>
    </joint>
    <joint name="robot_back_left_wheel_joint">
      <param name="id">0x02</param>
      <param name="encoder_resolution">4000</param>
      <param name="gearbox_ratio">9.56</param>
      <param name="spin">1</param>
      <command_interface name="position">
        <param name="min">0.0</param>
        <param name="max">0.0</param>
      </command_interface>
      <command_interface name="velocity">
        <param name="min">-18.8495</param>
        <param name="max">18.8495</param>
      </command_interface>
      <command_interface name="effort">
        <param name="min">-50</param>
        <param name="max">50</param>
      </command_interface>
      <state_interface name="position"/>
      <state_interface name="velocity"/>
    </joint>
    <joint name="robot_front_right_wheel_joint">
      <param name="id">0x03</param>
      <param name="encoder_resolution">4000</param>
      <param name="gearbox_ratio">9.56</param>
      <param name="spin">-1</param>
      <command_interface name="position">
        <param name="min">0.0</param>
        <param name="max">0.0</param>
      </command_interface>
      <command_interface name="velocity">
        <param name="min">-18.8495</param>
        <param name="max">18.8495</param>
      </command_interface>
      <command_interface name="effort">
        <param name="min">-50</param>
        <param name="max">50</param>
      </command_interface>
      <state_interface name="position"/>
      <state_interface name="velocity"/>
    </joint>
    <joint name="robot_back_right_wheel_joint">
      <param name="id">0x04</param>
      <param name="encoder_resolution">4000</param>
      <param name="gearbox_ratio">9.56</param>
      <param name="spin">-1</param>
      <command_interface name="position">
        <param name="min">0.0</param>
        <param name="max">0.0</param>
      </command_interface>
      <command_interface name="velocity">
        <param name="min">-18.8495</param>
        <param name="max">18.8495</param>
      </command_interface>
      <command_interface name="effort">
        <param name="min">-50</param>
        <param name="max">50</param>
      </command_interface>
      <state_interface name="position"/>
      <state_interface name="velocity"/>
    </joint>
  </ros2_control>
</robot>
