<?xml version="1.0" ?>
<!-- =================================================================================== -->
<!-- |    This document was autogenerated by xacro from rbrobout.urdf.xacro            | -->
<!-- |    EDITING THIS FILE BY HAND IS NOT RECOMMENDED                                 | -->
<!-- =================================================================================== -->
<robot name="rbrobout">
  <!-- ***************** -->
  <!-- Imported elements -->
  <!-- ***************** -->
  <!-- Import all posible elements defined in the urdf.xacro files. All these elements are defined as macro:xacros -->
  <!-- ***************** -->
  <!-- Imported elements -->
  <!-- ***************** -->
  <!-- First we import all posible elements defined in the urdf.xacro files. All these elements are defined as macro:xacros -->
  <!-- in kg-->
  <!-- This file unifies all sensors that can be used on simulation, defined as xacro:macros -->
  <!-- source en.wikipedia.org/wiki/List_of_moments_of_inertia-->
  <!-- $(find robotnik_sensors_gazebo)/config/camera/axis_m5013.yaml -->
  <!-- $(find robotnik_sensors_gazebo)/config/camera/axis_m5074.yaml-->
  <!-- $(find robotnik_sensors_gazebo)/config/camera/axis_m5525.yaml -->
  <!--$(find robotnik_sensors_gazebo)/config/camera/axis_m5526.yaml-->
  <!-- This file unifies all sensors that can be used on simulation, defined as xacro:macros -->
  <!-- source en.wikipedia.org/wiki/List_of_moments_of_inertia-->
  <!-- $(find robotnik_sensors_gazebo)/config/camera/axis_m5013.yaml -->
  <!-- $(find robotnik_sensors_gazebo)/config/camera/axis_m5074.yaml-->
  <!-- $(find robotnik_sensors_gazebo)/config/camera/axis_m5525.yaml -->
  <!--$(find robotnik_sensors_gazebo)/config/camera/axis_m5526.yaml-->
  <!-- Properties and Arguments -->
  <!-- *************** -->
  <!-- Robots Elements -->
  <!-- *************** -->
  <!-- Here we create the robot elements using the xacro:macros imported at the beggining of this file -->
  <!-- BASE FOOTPRINT -->
  <link name="robot_base_footprint">
    <visual>
      <origin rpy="0 0 0" xyz="0 0 0"/>
      <geometry>
        <box size="0.001 0.001 0.001"/>
      </geometry>
    </visual>
  </link>
  <joint name="robot_base_footprint_joint" type="fixed">
    <origin rpy="0 0 0" xyz="0 0 0.127"/>
    <!-- ${wheel_radius} property must be defined inside wheel description -->
    <parent link="robot_base_footprint"/>
    <child link="robot_base_link"/>
  </joint>
  <!-- BASE_LINK -->
  <link name="robot_base_link">
    <inertial>
      <mass value="200.0"/>
      <origin xyz="0 0 0.10"/>
      <inertia ixx="38.166666666666664" ixy="0" ixz="0" iyy="67.33333333333333" iyz="0" izz="104.16666666666667"/>
    </inertial>
    <visual>
      <origin rpy="0 0 0" xyz="0 0 0"/>
      <geometry>
        <mesh filename="package://robot_description/meshes/bases/rbrobout/robout_chassis.stl"/>
      </geometry>
      <material name="darkgrey">
        <color rgba="0.1 0.1 0.1 1"/>
      </material>
    </visual>
    <collision>
      <origin rpy="0 0 0 " xyz="0 0 0"/>
      <geometry>
        <mesh filename="package://robot_description/meshes/bases/rbrobout/robout_chassis.stl"/>
      </geometry>
    </collision>
  </link>
  <!-- DOCKING CONTACTS -->
  <!-- <joint name="${prefix}base_docking_joint" type="fixed">
            <origin xyz="0.284 0.012 0.068" rpy="0 0 0 " />
            <parent link="${prefix}base_link"/>
            <child link="${prefix}base_docking_contact_link" />
        </joint> -->
  <!-- DOCKING LINK -->
  <!-- <link name="${prefix}base_docking_contact_link" /> -->
  <joint name="robot_front_right_wheel_joint" type="continuous">
    <parent link="robot_base_link"/>
    <child link="robot_front_right_wheel_link"/>
    <origin rpy="0 0 0" xyz="0.558 -0.2865 0.0"/>
    <axis rpy="0 0 0" xyz="0 1 0"/>
    <limit effort="100" velocity="100"/>
    <joint_properties damping="0.5" friction="2.0"/>
  </joint>
  <link name="robot_front_right_wheel_link">
    <visual>
      <origin rpy="1.570796326795 0 0" xyz="0 0 0"/>
      <geometry>
        <mesh filename="package://robot_description/meshes/wheels/omni_wheel/robout_wheel.stl"/>
      </geometry>
      <material name="darkgrey">
        <color rgba="0.2 0.2 0.2 1"/>
      </material>
    </visual>
    <collision>
      <origin rpy="1.570796326795 0 0" xyz="0 0 0"/>
      <geometry>
        <cylinder length="0.087" radius="0.127"/>
      </geometry>
    </collision>
    <inertial>
      <mass value="6.5"/>
      <origin xyz="0 0 0"/>
      <inertia ixx="0.0303095" ixy="0" ixz="0" iyy="0.05241925" iyz="0" izz="0.0303095"/>
    </inertial>
  </link>
  <gazebo reference="robot_front_right_wheel_link">
    <mu1>0.90</mu1>
    <mu2>0.85</mu2>
    <kp>2.75e6</kp>
    <kd>8.25e1</kd>
    <fdir1>0 0 0</fdir1>
  </gazebo>
  <joint name="robot_front_left_wheel_joint" type="continuous">
    <parent link="robot_base_link"/>
    <child link="robot_front_left_wheel_link"/>
    <origin rpy="0 0 0" xyz="0.558 0.2865 0.0"/>
    <axis rpy="0 0 0" xyz="0 1 0"/>
    <limit effort="100" velocity="100"/>
    <joint_properties damping="0.5" friction="2.0"/>
  </joint>
  <link name="robot_front_left_wheel_link">
    <visual>
      <origin rpy="1.570796326795 0 0" xyz="0 0 0"/>
      <geometry>
        <mesh filename="package://robot_description/meshes/wheels/omni_wheel/robout_wheel.stl"/>
      </geometry>
      <material name="darkgrey">
        <color rgba="0.2 0.2 0.2 1"/>
      </material>
    </visual>
    <collision>
      <origin rpy="1.570796326795 0 0" xyz="0 0 0"/>
      <geometry>
        <cylinder length="0.087" radius="0.127"/>
      </geometry>
    </collision>
    <inertial>
      <mass value="6.5"/>
      <origin xyz="0 0 0"/>
      <inertia ixx="0.0303095" ixy="0" ixz="0" iyy="0.05241925" iyz="0" izz="0.0303095"/>
    </inertial>
  </link>
  <gazebo reference="robot_front_left_wheel_link">
    <mu1>0.90</mu1>
    <mu2>0.85</mu2>
    <kp>2.75e6</kp>
    <kd>8.25e1</kd>
    <fdir1>0 0 0</fdir1>
  </gazebo>
  <joint name="robot_back_left_wheel_joint" type="continuous">
    <parent link="robot_base_link"/>
    <child link="robot_back_left_wheel_link"/>
    <origin rpy="0 0 0" xyz="-0.558 0.2865 0.0"/>
    <axis rpy="0 0 0" xyz="0 1 0"/>
    <limit effort="100" velocity="100"/>
    <joint_properties damping="0.5" friction="2.0"/>
  </joint>
  <link name="robot_back_left_wheel_link">
    <visual>
      <origin rpy="1.570796326795 0 0" xyz="0 0 0"/>
      <geometry>
        <mesh filename="package://robot_description/meshes/wheels/omni_wheel/robout_wheel.stl"/>
      </geometry>
      <material name="darkgrey">
        <color rgba="0.2 0.2 0.2 1"/>
      </material>
    </visual>
    <collision>
      <origin rpy="1.570796326795 0 0" xyz="0 0 0"/>
      <geometry>
        <cylinder length="0.087" radius="0.127"/>
      </geometry>
    </collision>
    <inertial>
      <mass value="6.5"/>
      <origin xyz="0 0 0"/>
      <inertia ixx="0.0303095" ixy="0" ixz="0" iyy="0.05241925" iyz="0" izz="0.0303095"/>
    </inertial>
  </link>
  <gazebo reference="robot_back_left_wheel_link">
    <mu1>0.90</mu1>
    <mu2>0.85</mu2>
    <kp>2.75e6</kp>
    <kd>8.25e1</kd>
    <fdir1>0 0 0</fdir1>
  </gazebo>
  <joint name="robot_back_right_wheel_joint" type="continuous">
    <parent link="robot_base_link"/>
    <child link="robot_back_right_wheel_link"/>
    <origin rpy="0 0 0" xyz="-0.558 -0.2865 0.0"/>
    <axis rpy="0 0 0" xyz="0 1 0"/>
    <limit effort="100" velocity="100"/>
    <joint_properties damping="0.5" friction="2.0"/>
  </joint>
  <link name="robot_back_right_wheel_link">
    <visual>
      <origin rpy="1.570796326795 0 0" xyz="0 0 0"/>
      <geometry>
        <mesh filename="package://robot_description/meshes/wheels/omni_wheel/robout_wheel.stl"/>
      </geometry>
      <material name="darkgrey">
        <color rgba="0.2 0.2 0.2 1"/>
      </material>
    </visual>
    <collision>
      <origin rpy="1.570796326795 0 0" xyz="0 0 0"/>
      <geometry>
        <cylinder length="0.087" radius="0.127"/>
      </geometry>
    </collision>
    <inertial>
      <mass value="6.5"/>
      <origin xyz="0 0 0"/>
      <inertia ixx="0.0303095" ixy="0" ixz="0" iyy="0.05241925" iyz="0" izz="0.0303095"/>
    </inertial>
  </link>
  <gazebo reference="robot_back_right_wheel_link">
    <mu1>0.90</mu1>
    <mu2>0.85</mu2>
    <kp>2.75e6</kp>
    <kd>8.25e1</kd>
    <fdir1>0 0 0</fdir1>
  </gazebo>
  <joint name="robot_vectornav_base_joint" type="fixed">
    <origin rpy="0 0 0" xyz="0.242 -0.053 -0.028"/>
    <parent link="robot_base_link"/>
    <child link="robot_vectornav_base_link"/>
  </joint>
  <link name="robot_vectornav_base_link">
    <inertial>
      <origin rpy="0 0 0" xyz="0.0 0 0.01"/>
      <mass value="0.05"/>
      <inertia ixx="3.3333333333333337e-06" ixy="0" ixz="0" iyy="3.3333333333333337e-06" iyz="0" izz="3.3333333333333337e-06"/>
    </inertial>
    <visual>
      <origin rpy="0 0 0" xyz="0 0 0"/>
      <material name="vectornav_imu_color">
        <color rgba="1 0 0 1"/>
      </material>
      <geometry>
        <mesh filename="package://robotnik_sensors/meshes/imu/vectornav_vn100.stl"/>
      </geometry>
    </visual>
    <collision>
      <origin rpy="0 0 0" xyz="0 0 0.0045"/>
      <geometry>
        <box size="0.036 0.037 0.009"/>
      </geometry>
    </collision>
  </link>
  <joint name="robot_vectornav_joint" type="fixed">
    <axis xyz="1 0 0"/>
    <origin xyz="-0.00745 0.0 0.0088"/>
    <parent link="robot_vectornav_base_link"/>
    <child link="robot_vectornav_link"/>
  </joint>
  <link name="robot_vectornav_link"/>
  <gazebo reference="robot_vectornav_link">
    <gravity>true</gravity>
    <sensor name="imu_sensor" type="imu">
      <always_on>true</always_on>
      <update_rate>200.0</update_rate>
      <visualize>true</visualize>
      <imu>
        <orientation>
          <x>
            <noise type="gaussian">
              <mean>0.0</mean>
              <stddev>2e-3</stddev>
            </noise>
          </x>
          <y>
            <noise type="gaussian">
              <mean>0.0</mean>
              <stddev>2e-3</stddev>
            </noise>
          </y>
          <z>
            <noise type="gaussian">
              <mean>0.0</mean>
              <stddev>2e-3</stddev>
            </noise>
          </z>
        </orientation>
        <angular_velocity>
          <x>
            <noise type="gaussian">
              <mean>0.0</mean>
              <stddev>2e-4</stddev>
            </noise>
          </x>
          <y>
            <noise type="gaussian">
              <mean>0.0</mean>
              <stddev>2e-4</stddev>
            </noise>
          </y>
          <z>
            <noise type="gaussian">
              <mean>0.0</mean>
              <stddev>2e-4</stddev>
            </noise>
          </z>
        </angular_velocity>
        <linear_acceleration>
          <x>
            <noise type="gaussian">
              <mean>0.0</mean>
              <stddev>1.7e-2</stddev>
            </noise>
          </x>
          <y>
            <noise type="gaussian">
              <mean>0.0</mean>
              <stddev>1.7e-2</stddev>
            </noise>
          </y>
          <z>
            <noise type="gaussian">
              <mean>0.0</mean>
              <stddev>1.7e-2</stddev>
            </noise>
          </z>
        </linear_acceleration>
        <orientation_enabled>true</orientation_enabled>
        <angular_velocity_enabled>true</angular_velocity_enabled>
        <linear_acceleration_enabled>true</linear_acceleration_enabled>
      </imu>
      <plugin filename="libignition-gazebo6-imu-system.so" name="ignition::gazebo::systems::Imu">
          </plugin>
      <topic>robot/imu/data</topic>
      <gz_frame_id>robot_vectornav_link</gz_frame_id>
    </sensor>
  </gazebo>
  <gazebo reference="robot_vectornav_base_link">
    <material>Gazebo/Red</material>
  </gazebo>
  <joint name="robot_front_rgbd_camera_base_joint" type="fixed">
    <origin rpy="0 0 0" xyz="0.835 0.0 0.1555"/>
    <parent link="robot_base_link"/>
    <child link="robot_front_rgbd_camera_base_link"/>
  </joint>
  <link name="robot_front_rgbd_camera_base_link"/>
  <!-- camera body, with origin at bottom screw mount -->
  <joint name="robot_front_rgbd_camera_joint" type="fixed">
    <parent link="robot_front_rgbd_camera_base_link"/>
    <child link="robot_front_rgbd_camera_link"/>
    <origin rpy="0 0 0" xyz="0.01 0.02 0"/>
    <child link="robot_front_rgbd_camera_link"/>
  </joint>
  <link name="robot_front_rgbd_camera_link">
    <!-- camera link is aligned with the infrared sensor 1 that is "in the middle of the camera", not the one in the edge -->
    <visual>
      <origin rpy="1.5707963267948966 0 1.5707963267948966" xyz="0.0149 -0.0175 0"/>
      <geometry>
        <!-- <box size="${d435_cam_width} ${d435_cam_height} ${d435_cam_depth}"/> -->
        <mesh filename="package://robotnik_sensors/meshes/depth/intel_realsense_d435/intel_d435_color.dae"/>
      </geometry>
    </visual>
    <collision>
      <origin rpy="0 0 0" xyz="0 -0.0175 0"/>
      <geometry>
        <box size="0.02505 0.09 0.025"/>
      </geometry>
    </collision>
    <inertial>
      <origin rpy="0 0 0" xyz="0.0025 -0.015 0.0"/>
      <mass value="0.1"/>
      <inertia ixx="7.270833333333333e-05" ixy="0" ixz="0" iyy="1.041666666666667e-05" iyz="0" izz="7.270833333333333e-05"/>
    </inertial>
  </link>
  <!-- Use the nominal extrinsics between camera frames if the calibrated extrinsics aren't being published. e.g. running the device in simulation  -->
  <!-- camera depth joints and links -->
  <joint name="robot_front_rgbd_camera_depth_joint" type="fixed">
    <origin rpy="0 0 0" xyz="0 0 0"/>
    <parent link="robot_front_rgbd_camera_link"/>
    <child link="robot_front_rgbd_camera_depth_frame"/>
  </joint>
  <link name="robot_front_rgbd_camera_depth_frame"/>
  <joint name="robot_front_rgbd_camera_depth_optical_joint" type="fixed">
    <origin rpy="-1.5707963267948966 0 -1.5707963267948966" xyz="0 0 0"/>
    <parent link="robot_front_rgbd_camera_depth_frame"/>
    <child link="robot_front_rgbd_camera_depth_optical_frame"/>
  </joint>
  <link name="robot_front_rgbd_camera_depth_optical_frame"/>
  <!-- camera left IR joints and links -->
  <joint name="robot_front_rgbd_camera_infra1_joint" type="fixed">
    <origin rpy="0 0 0" xyz="0 0.0 0"/>
    <parent link="robot_front_rgbd_camera_link"/>
    <child link="robot_front_rgbd_camera_infra1_frame"/>
  </joint>
  <link name="robot_front_rgbd_camera_infra1_frame"/>
  <joint name="robot_front_rgbd_camera_infra1_optical_joint" type="fixed">
    <origin rpy="-1.5707963267948966 0 -1.5707963267948966" xyz="0 0 0"/>
    <parent link="robot_front_rgbd_camera_infra1_frame"/>
    <child link="robot_front_rgbd_camera_infra1_optical_frame"/>
  </joint>
  <link name="robot_front_rgbd_camera_infra1_optical_frame"/>
  <!-- camera right IR joints and links -->
  <joint name="robot_front_rgbd_camera_infra2_joint" type="fixed">
    <origin rpy="0 0 0" xyz="0 -0.05 0"/>
    <parent link="robot_front_rgbd_camera_link"/>
    <child link="robot_front_rgbd_camera_infra2_frame"/>
  </joint>
  <link name="robot_front_rgbd_camera_infra2_frame"/>
  <joint name="robot_front_rgbd_camera_infra2_optical_joint" type="fixed">
    <origin rpy="-1.5707963267948966 0 -1.5707963267948966" xyz="0 0 0"/>
    <parent link="robot_front_rgbd_camera_infra2_frame"/>
    <child link="robot_front_rgbd_camera_infra2_optical_frame"/>
  </joint>
  <link name="robot_front_rgbd_camera_infra2_optical_frame"/>
  <!-- camera color joints and links -->
  <joint name="robot_front_rgbd_camera_color_joint" type="fixed">
    <origin rpy="0 0 0" xyz="0 0.015 0"/>
    <parent link="robot_front_rgbd_camera_link"/>
    <child link="robot_front_rgbd_camera_color_frame"/>
  </joint>
  <link name="robot_front_rgbd_camera_color_frame"/>
  <joint name="robot_front_rgbd_camera_color_optical_joint" type="fixed">
    <origin rpy="-1.5707963267948966 0 -1.5707963267948966" xyz="0 0 0"/>
    <parent link="robot_front_rgbd_camera_color_frame"/>
    <child link="robot_front_rgbd_camera_color_optical_frame"/>
  </joint>
  <link name="robot_front_rgbd_camera_color_optical_frame"/>
  <gazebo reference="robot_front_rgbd_camera_color_frame">
    <sensor name="front_camera_color" type="camera">
      <camera name="front_camera_color">
        <horizontal_fov>1.2112585008840648</horizontal_fov>
        <vertical_fov>0.6806784082777885</vertical_fov>
        <image>
          <width>1920</width>
          <height>1080</height>
          <format>RGB_INT8</format>
        </image>
        <clip>
          <near>0.1</near>
          <far>100</far>
        </clip>
        <noise>
          <type>gaussian</type>
          <mean>0.0</mean>
          <stddev>0.05</stddev>
        </noise>
      </camera>
      <always_on>1</always_on>
      <update_rate>30</update_rate>
      <visualize>false</visualize>
      <topic>robot/front_camera_color/color/image_raw</topic>
      <gz_frame_id>robot_front_rgbd_camera_color_optical_frame</gz_frame_id>
      <camera_info_topic>robot/front_camera_color/color/camera_info</camera_info_topic>
    </sensor>
  </gazebo>
  <gazebo reference="robot_front_rgbd_camera_infra2_frame">
    <sensor name="front_camera_irred1" type="camera">
      <camera name="front_camera_irred1">
        <horizontal_fov>1.4870205226991688</horizontal_fov>
        <vertical_fov>0.8377580409572782</vertical_fov>
        <image>
          <width>1280</width>
          <height>720</height>
          <format>L_INT8</format>
        </image>
        <clip>
          <near>0.1</near>
          <far>100</far>
        </clip>
        <noise>
          <type>gaussian</type>
          <mean>0.0</mean>
          <stddev>0.05</stddev>
        </noise>
      </camera>
      <always_on>1</always_on>
      <update_rate>30</update_rate>
      <visualize>false</visualize>
      <topic>robot/front_camera_irred1/ired/image_raw</topic>
      <gz_frame_id>robot_front_rgbd_camera_infra1_optical_frame</gz_frame_id>
      <camera_info_topic>robot/front_camera_irred1/ired/camera_info</camera_info_topic>
    </sensor>
  </gazebo>
  <gazebo reference="robot_front_rgbd_camera_infra2_frame">
    <sensor name="front_camera_irred2" type="camera">
      <camera name="front_camera_irred2">
        <horizontal_fov>1.4870205226991688</horizontal_fov>
        <vertical_fov>0.8377580409572782</vertical_fov>
        <image>
          <width>1280</width>
          <height>720</height>
          <format>L_INT8</format>
        </image>
        <clip>
          <near>0.1</near>
          <far>100</far>
        </clip>
        <noise>
          <type>gaussian</type>
          <mean>0.0</mean>
          <stddev>0.05</stddev>
        </noise>
      </camera>
      <always_on>1</always_on>
      <update_rate>30</update_rate>
      <visualize>false</visualize>
      <topic>robot/front_camera_irred2/ired/image_raw</topic>
      <gz_frame_id>robot_front_rgbd_camera_infra2_optical_frame</gz_frame_id>
      <camera_info_topic>robot/front_camera_irred2/ired/camera_info</camera_info_topic>
    </sensor>
  </gazebo>
  <gazebo reference="robot_front_rgbd_camera_depth_frame">
    <sensor name="front_camera_depth" type="depth">
      <camera name="front_camera_depth">
        <camera_info_topic>front_camera_depth/depth/camera_info</camera_info_topic>
        <horizontal_fov>1.4870205226991688</horizontal_fov>
        <vertical_fov>0.8377580409572782</vertical_fov>
        <image>
          <width>1280</width>
          <height>720</height>
          <format>B8G8R8</format>
        </image>
        <clip>
          <near>0.1</near>
          <far>100</far>
        </clip>
        <noise>
          <type>gaussian</type>
          <mean>0.0</mean>
          <stddev>0.100</stddev>
        </noise>
      </camera>
      <always_on>1</always_on>
      <update_rate>90</update_rate>
      <visualize>false</visualize>
      <topic>robot/front_camera_depth/depth/image_raw</topic>
      <gz_frame_id>robot_front_rgbd_camera_depth_optical_frame</gz_frame_id>
    </sensor>
  </gazebo>
  <joint name="robot_rear_rgbd_camera_base_joint" type="fixed">
    <origin rpy="0 3.14159265359 0" xyz="-0.835 0.0 0.1555"/>
    <parent link="robot_base_link"/>
    <child link="robot_rear_rgbd_camera_base_link"/>
  </joint>
  <link name="robot_rear_rgbd_camera_base_link"/>
  <!-- camera body, with origin at bottom screw mount -->
  <joint name="robot_rear_rgbd_camera_joint" type="fixed">
    <parent link="robot_rear_rgbd_camera_base_link"/>
    <child link="robot_rear_rgbd_camera_link"/>
    <origin rpy="0 0 0" xyz="0.01 0.02 0"/>
    <child link="robot_rear_rgbd_camera_link"/>
  </joint>
  <link name="robot_rear_rgbd_camera_link">
    <!-- camera link is aligned with the infrared sensor 1 that is "in the middle of the camera", not the one in the edge -->
    <visual>
      <origin rpy="1.5707963267948966 0 1.5707963267948966" xyz="0.0149 -0.0175 0"/>
      <geometry>
        <!-- <box size="${d435_cam_width} ${d435_cam_height} ${d435_cam_depth}"/> -->
        <mesh filename="package://robotnik_sensors/meshes/depth/intel_realsense_d435/intel_d435_color.dae"/>
      </geometry>
    </visual>
    <collision>
      <origin rpy="0 0 0" xyz="0 -0.0175 0"/>
      <geometry>
        <box size="0.02505 0.09 0.025"/>
      </geometry>
    </collision>
    <inertial>
      <origin rpy="0 0 0" xyz="0.0025 -0.015 0.0"/>
      <mass value="0.1"/>
      <inertia ixx="7.270833333333333e-05" ixy="0" ixz="0" iyy="1.041666666666667e-05" iyz="0" izz="7.270833333333333e-05"/>
    </inertial>
  </link>
  <!-- Use the nominal extrinsics between camera frames if the calibrated extrinsics aren't being published. e.g. running the device in simulation  -->
  <!-- camera depth joints and links -->
  <joint name="robot_rear_rgbd_camera_depth_joint" type="fixed">
    <origin rpy="0 0 0" xyz="0 0 0"/>
    <parent link="robot_rear_rgbd_camera_link"/>
    <child link="robot_rear_rgbd_camera_depth_frame"/>
  </joint>
  <link name="robot_rear_rgbd_camera_depth_frame"/>
  <joint name="robot_rear_rgbd_camera_depth_optical_joint" type="fixed">
    <origin rpy="-1.5707963267948966 0 -1.5707963267948966" xyz="0 0 0"/>
    <parent link="robot_rear_rgbd_camera_depth_frame"/>
    <child link="robot_rear_rgbd_camera_depth_optical_frame"/>
  </joint>
  <link name="robot_rear_rgbd_camera_depth_optical_frame"/>
  <!-- camera left IR joints and links -->
  <joint name="robot_rear_rgbd_camera_infra1_joint" type="fixed">
    <origin rpy="0 0 0" xyz="0 0.0 0"/>
    <parent link="robot_rear_rgbd_camera_link"/>
    <child link="robot_rear_rgbd_camera_infra1_frame"/>
  </joint>
  <link name="robot_rear_rgbd_camera_infra1_frame"/>
  <joint name="robot_rear_rgbd_camera_infra1_optical_joint" type="fixed">
    <origin rpy="-1.5707963267948966 0 -1.5707963267948966" xyz="0 0 0"/>
    <parent link="robot_rear_rgbd_camera_infra1_frame"/>
    <child link="robot_rear_rgbd_camera_infra1_optical_frame"/>
  </joint>
  <link name="robot_rear_rgbd_camera_infra1_optical_frame"/>
  <!-- camera right IR joints and links -->
  <joint name="robot_rear_rgbd_camera_infra2_joint" type="fixed">
    <origin rpy="0 0 0" xyz="0 -0.05 0"/>
    <parent link="robot_rear_rgbd_camera_link"/>
    <child link="robot_rear_rgbd_camera_infra2_frame"/>
  </joint>
  <link name="robot_rear_rgbd_camera_infra2_frame"/>
  <joint name="robot_rear_rgbd_camera_infra2_optical_joint" type="fixed">
    <origin rpy="-1.5707963267948966 0 -1.5707963267948966" xyz="0 0 0"/>
    <parent link="robot_rear_rgbd_camera_infra2_frame"/>
    <child link="robot_rear_rgbd_camera_infra2_optical_frame"/>
  </joint>
  <link name="robot_rear_rgbd_camera_infra2_optical_frame"/>
  <!-- camera color joints and links -->
  <joint name="robot_rear_rgbd_camera_color_joint" type="fixed">
    <origin rpy="0 0 0" xyz="0 0.015 0"/>
    <parent link="robot_rear_rgbd_camera_link"/>
    <child link="robot_rear_rgbd_camera_color_frame"/>
  </joint>
  <link name="robot_rear_rgbd_camera_color_frame"/>
  <joint name="robot_rear_rgbd_camera_color_optical_joint" type="fixed">
    <origin rpy="-1.5707963267948966 0 -1.5707963267948966" xyz="0 0 0"/>
    <parent link="robot_rear_rgbd_camera_color_frame"/>
    <child link="robot_rear_rgbd_camera_color_optical_frame"/>
  </joint>
  <link name="robot_rear_rgbd_camera_color_optical_frame"/>
  <gazebo reference="robot_rear_rgbd_camera_color_frame">
    <sensor name="rear_camera_color" type="camera">
      <camera name="rear_camera_color">
        <horizontal_fov>1.2112585008840648</horizontal_fov>
        <vertical_fov>0.6806784082777885</vertical_fov>
        <image>
          <width>1920</width>
          <height>1080</height>
          <format>RGB_INT8</format>
        </image>
        <clip>
          <near>0.1</near>
          <far>100</far>
        </clip>
        <noise>
          <type>gaussian</type>
          <mean>0.0</mean>
          <stddev>0.05</stddev>
        </noise>
      </camera>
      <always_on>1</always_on>
      <update_rate>30</update_rate>
      <visualize>false</visualize>
      <topic>robot/rear_camera_color/color/image_raw</topic>
      <gz_frame_id>robot_rear_rgbd_camera_color_optical_frame</gz_frame_id>
      <camera_info_topic>robot/rear_camera_color/color/camera_info</camera_info_topic>
    </sensor>
  </gazebo>
  <gazebo reference="robot_rear_rgbd_camera_infra2_frame">
    <sensor name="rear_camera_irred1" type="camera">
      <camera name="rear_camera_irred1">
        <horizontal_fov>1.4870205226991688</horizontal_fov>
        <vertical_fov>0.8377580409572782</vertical_fov>
        <image>
          <width>1280</width>
          <height>720</height>
          <format>L_INT8</format>
        </image>
        <clip>
          <near>0.1</near>
          <far>100</far>
        </clip>
        <noise>
          <type>gaussian</type>
          <mean>0.0</mean>
          <stddev>0.05</stddev>
        </noise>
      </camera>
      <always_on>1</always_on>
      <update_rate>30</update_rate>
      <visualize>false</visualize>
      <topic>robot/rear_camera_irred1/ired/image_raw</topic>
      <gz_frame_id>robot_rear_rgbd_camera_infra1_optical_frame</gz_frame_id>
      <camera_info_topic>robot/rear_camera_irred1/ired/camera_info</camera_info_topic>
    </sensor>
  </gazebo>
  <gazebo reference="robot_rear_rgbd_camera_infra2_frame">
    <sensor name="rear_camera_irred2" type="camera">
      <camera name="rear_camera_irred2">
        <horizontal_fov>1.4870205226991688</horizontal_fov>
        <vertical_fov>0.8377580409572782</vertical_fov>
        <image>
          <width>1280</width>
          <height>720</height>
          <format>L_INT8</format>
        </image>
        <clip>
          <near>0.1</near>
          <far>100</far>
        </clip>
        <noise>
          <type>gaussian</type>
          <mean>0.0</mean>
          <stddev>0.05</stddev>
        </noise>
      </camera>
      <always_on>1</always_on>
      <update_rate>30</update_rate>
      <visualize>false</visualize>
      <topic>robot/rear_camera_irred2/ired/image_raw</topic>
      <gz_frame_id>robot_rear_rgbd_camera_infra2_optical_frame</gz_frame_id>
      <camera_info_topic>robot/rear_camera_irred2/ired/camera_info</camera_info_topic>
    </sensor>
  </gazebo>
  <gazebo reference="robot_rear_rgbd_camera_depth_frame">
    <sensor name="rear_camera_depth" type="depth">
      <camera name="rear_camera_depth">
        <camera_info_topic>rear_camera_depth/depth/camera_info</camera_info_topic>
        <horizontal_fov>1.4870205226991688</horizontal_fov>
        <vertical_fov>0.8377580409572782</vertical_fov>
        <image>
          <width>1280</width>
          <height>720</height>
          <format>B8G8R8</format>
        </image>
        <clip>
          <near>0.1</near>
          <far>100</far>
        </clip>
        <noise>
          <type>gaussian</type>
          <mean>0.0</mean>
          <stddev>0.100</stddev>
        </noise>
      </camera>
      <always_on>1</always_on>
      <update_rate>90</update_rate>
      <visualize>false</visualize>
      <topic>robot/rear_camera_depth/depth/image_raw</topic>
      <gz_frame_id>robot_rear_rgbd_camera_depth_optical_frame</gz_frame_id>
    </sensor>
  </gazebo>
  <joint name="robot_front_laser_base_joint" type="fixed">
    <origin rpy="0 0 0.7853981633975" xyz="0.8 0.3666 -0.06"/>
    <parent link="robot_base_link"/>
    <child link="robot_front_laser_base_link"/>
  </joint>
  <link name="robot_front_laser_base_link">
    <visual>
      <origin rpy="0 0 0" xyz="0 0 0"/>
      <geometry>
        <mesh filename="package://robotnik_sensors/meshes/2d_lidar/sick/microscan3.dae"/>
      </geometry>
    </visual>
    <collision>
      <origin rpy="0 0 0" xyz="0 0 0"/>
      <geometry>
        <mesh filename="package://robotnik_sensors/meshes/2d_lidar/sick/microscan3.dae"/>
      </geometry>
    </collision>
    <inertial>
      <mass value="1.15"/>
      <origin rpy="0 0 0" xyz="0 0 0.075"/>
      <inertia ixx="0.0033370124999999996" ixy="0" ixz="0" iyy="0.003358383333333333" iyz="0" izz="0.0023828958333333332"/>
    </inertial>
  </link>
  <joint name="robot_front_laser_joint" type="fixed">
    <origin rpy="0 0 0" xyz="0.0 0 0.110"/>
    <parent link="robot_front_laser_base_link"/>
    <child link="robot_front_laser_link"/>
  </joint>
  <link name="robot_front_laser_link"/>
  <gazebo reference="robot_front_laser_link">
    <sensor name="front_laser" type="gpu_lidar">
      <pose>0 0 0 0 0 0</pose>
      <visualize>false</visualize>
      <update_rate>30</update_rate>
      <lidar>
        <scan>
          <horizontal>
            <samples>700</samples>
            <resolution>1</resolution>
            <min_angle>-2.35</min_angle>
            <max_angle>2.35</max_angle>
          </horizontal>
        </scan>
        <range>
          <min>0.05</min>
          <max>64.0</max>
          <resolution>0.00575</resolution>
        </range>
        <noise>
          <type>gaussian</type>
          <mean>0.0</mean>
          <stddev>0.03</stddev>
        </noise>
      </lidar>
      <topic> robot/front_laser/scan </topic>
      <gz_frame_id> robot_front_laser_link </gz_frame_id>
    </sensor>
  </gazebo>
  <joint name="robot_rear_laser_base_joint" type="fixed">
    <origin rpy="0 0 -2.3561944901925003" xyz="-0.8 -0.3666 -0.06"/>
    <parent link="robot_base_link"/>
    <child link="robot_rear_laser_base_link"/>
  </joint>
  <link name="robot_rear_laser_base_link">
    <visual>
      <origin rpy="0 0 0" xyz="0 0 0"/>
      <geometry>
        <mesh filename="package://robotnik_sensors/meshes/2d_lidar/sick/microscan3.dae"/>
      </geometry>
    </visual>
    <collision>
      <origin rpy="0 0 0" xyz="0 0 0"/>
      <geometry>
        <mesh filename="package://robotnik_sensors/meshes/2d_lidar/sick/microscan3.dae"/>
      </geometry>
    </collision>
    <inertial>
      <mass value="1.15"/>
      <origin rpy="0 0 0" xyz="0 0 0.075"/>
      <inertia ixx="0.0033370124999999996" ixy="0" ixz="0" iyy="0.003358383333333333" iyz="0" izz="0.0023828958333333332"/>
    </inertial>
  </link>
  <joint name="robot_rear_laser_joint" type="fixed">
    <origin rpy="0 0 0" xyz="0.0 0 0.110"/>
    <parent link="robot_rear_laser_base_link"/>
    <child link="robot_rear_laser_link"/>
  </joint>
  <link name="robot_rear_laser_link"/>
  <gazebo reference="robot_rear_laser_link">
    <sensor name="rear_laser" type="gpu_lidar">
      <pose>0 0 0 0 0 0</pose>
      <visualize>false</visualize>
      <update_rate>30</update_rate>
      <lidar>
        <scan>
          <horizontal>
            <samples>700</samples>
            <resolution>1</resolution>
            <min_angle>-2.35</min_angle>
            <max_angle>2.35</max_angle>
          </horizontal>
        </scan>
        <range>
          <min>0.05</min>
          <max>64.0</max>
          <resolution>0.00575</resolution>
        </range>
        <noise>
          <type>gaussian</type>
          <mean>0.0</mean>
          <stddev>0.03</stddev>
        </noise>
      </lidar>
      <topic> robot/rear_laser/scan </topic>
      <gz_frame_id> robot_rear_laser_link </gz_frame_id>
    </sensor>
  </gazebo>
  <gazebo>
    <plugin filename="ign_ros2_control-system" name="ign_ros2_control::IgnitionROS2ControlPlugin">
      <robot_param>robot_description</robot_param>
      <robot_param_node>robot_state_publisher</robot_param_node>
      <parameters>/home/joel/Documentos/GitHub/Robotnik_practicas/Robotnik_ws/install/robot_description/share/robot_description/simulators/gazebo_ignition/rbrobout/rbrobout_controller_params.yaml</parameters>
      <ros>
        <namespace>/robot</namespace>
      </ros>
    </plugin>
  </gazebo>
  <ros2_control name="IgnitionSystem" type="system">
    <hardware>
      <plugin>ign_ros2_control/IgnitionSystem</plugin>
    </hardware>
    <joint name="robot_front_left_wheel_joint">
      <command_interface name="velocity">
        <param name="min">-10</param>
        <param name="max">10</param>
      </command_interface>
      <state_interface name="position"/>
      <state_interface name="velocity"/>
      <state_interface name="effort"/>
    </joint>
    <joint name="robot_front_right_wheel_joint">
      <command_interface name="velocity">
        <param name="min">-10</param>
        <param name="max">10</param>
      </command_interface>
      <state_interface name="position"/>
      <state_interface name="velocity"/>
      <state_interface name="effort"/>
    </joint>
    <joint name="robot_back_left_wheel_joint">
      <command_interface name="velocity">
        <param name="min">-20</param>
        <param name="max">20</param>
      </command_interface>
      <state_interface name="position"/>
      <state_interface name="velocity"/>
      <state_interface name="effort"/>
    </joint>
    <joint name="robot_back_right_wheel_joint">
      <command_interface name="velocity">
        <param name="min">-20</param>
        <param name="max">20</param>
      </command_interface>
      <state_interface name="position"/>
      <state_interface name="velocity"/>
      <state_interface name="effort"/>
    </joint>
    <joint name="robot_lift_ewellix_lift_top_joint">
      <command_interface name="position">
        <param name="min">-20</param>
        <param name="max">20</param>
      </command_interface>
      <state_interface name="position"/>
      <state_interface name="velocity"/>
      <state_interface name="effort"/>
    </joint>
  </ros2_control>
  <gazebo>
    <plugin filename="libignition-gazebo-diff-drive-system.so" name="ignition::gazebo::systems::DiffDrive">
      <left_joint>robot_front_left_wheel_joint</left_joint>
      <right_joint>robot_front_right_wheel_joint</right_joint>
      <wheel_separation>0.573</wheel_separation>
      <wheel_radius>0.127</wheel_radius>
      <odom_publish_frequency>1</odom_publish_frequency>
      <topic>cmd_vel</topic>
      <frame_id>robot_odom</frame_id>
      <child_frame_id>robot_base_footprint</child_frame_id>
    </plugin>
  </gazebo>
  <gazebo>
    <plugin filename="libignition-gazebo-diff-drive-system.so" name="ignition::gazebo::systems::DiffDrive">
      <left_joint>robot_back_left_wheel_joint</left_joint>
      <right_joint>robot_back_right_wheel_joint</right_joint>
      <wheel_separation>0.573</wheel_separation>
      <wheel_radius>0.127</wheel_radius>
      <odom_publish_frequency>0</odom_publish_frequency>
      <publish_odom>false</publish_odom>
      <publish_odom_tf>false</publish_odom_tf>
      <topic>cmd_vel_rear</topic>
      <frame_id>robot_odom</frame_id>
      <child_frame_id>robot_base_footprint</child_frame_id>
    </plugin>
  </gazebo>
</robot>
